[2023-03-17 00:56:01] [INFO] INFO, 上传完成
[2023-03-20 00:43:06] [INFO] INFO, 上传完成
[2023-03-20 00:54:30] [INFO] INFO, 上传完成
[2023-03-20 00:54:30] [INFO] INFO, 上传完成
[2023-03-20 00:57:26] [INFO] INFO, 上传完成
[2023-03-20 00:57:26] [INFO] INFO, 上传完成
[2023-03-20 00:57:26] [INFO] INFO, 上传完成
[2023-03-20 01:10:29] [INFO] INFO, 上传完成
[2023-03-20 01:10:29] [INFO] INFO, 上传完成
[2023-03-20 01:10:29] [INFO] INFO, 上传完成
[2023-03-20 01:10:29] [INFO] INFO, 上传完成
[2023-03-20 22:53:27] [INFO] INFO, 上传完成
[2023-03-20 22:55:07] [INFO] INFO, 上传完成
[2023-03-20 22:58:48] [INFO] INFO, 上传完成
[2023-03-20 22:59:30] [INFO] INFO, 上传完成
[2023-03-20 23:00:53] [INFO] INFO, 上传完成
[2023-03-20 23:05:26] [INFO] ERROR, 目录存在，请重试
[2023-03-20 23:07:55] [ERROR] ERROR, 目录存在，请重试
[2023-03-20 23:28:06] [ERROR] dir: /Users/libangguo/Downloads/files/1679324453445722, Directory already exists, please try again
[2023-03-20 23:31:27] [ERROR] taskID: 22, failed to save feature file, error:Traceback (most recent call last):
  File "/Users/libangguo/python/project/data_canal/upload.py", line 60, in upLoad
    afeature_files.save(os.path.join(curPath, feature_files.filename))
    ^^^^^^^^^^^^^^
NameError: name 'afeature_files' is not defined

[2023-03-20 23:33:06] [INFO] task 23 upload success
[2023-03-21 00:12:34] [INFO] task 24 upload success
[2023-03-21 00:33:56] [ERROR] failed to get task, error:error! 127.0.0.1 - 3306: select select * from task1 where status='progress' failed!! 
Traceback (most recent call last):
  File "/Users/libangguo/python/project/data_canal/mysqlConnect.py", line 84, in querydata
    cursor.execute(sql)
  File "/opt/homebrew/lib/python3.11/site-packages/pymysql/cursors.py", line 148, in execute
    result = self._query(query)
             ^^^^^^^^^^^^^^^^^^
  File "/opt/homebrew/lib/python3.11/site-packages/pymysql/cursors.py", line 310, in _query
    conn.query(q)
  File "/opt/homebrew/lib/python3.11/site-packages/pymysql/connections.py", line 548, in query
    self._affected_rows = self._read_query_result(unbuffered=unbuffered)
                          ^^^^^^^^^^^^^^^^^^^^^^^^^^^^^^^^^^^^^^^^^^^^^^
  File "/opt/homebrew/lib/python3.11/site-packages/pymysql/connections.py", line 775, in _read_query_result
    result.read()
  File "/opt/homebrew/lib/python3.11/site-packages/pymysql/connections.py", line 1156, in read
    first_packet = self.connection._read_packet()
                   ^^^^^^^^^^^^^^^^^^^^^^^^^^^^^^
  File "/opt/homebrew/lib/python3.11/site-packages/pymysql/connections.py", line 725, in _read_packet
    packet.raise_for_error()
  File "/opt/homebrew/lib/python3.11/site-packages/pymysql/protocol.py", line 221, in raise_for_error
    err.raise_mysql_exception(self._data)
  File "/opt/homebrew/lib/python3.11/site-packages/pymysql/err.py", line 143, in raise_mysql_exception
    raise errorclass(errno, errval)
pymysql.err.ProgrammingError: (1146, "Table 'data_canal.task1' doesn't exist")
 
[2023-03-21 00:35:10] [ERROR] failed to get task, error:error! 127.0.0.1 - 3306: select select * from task1 where status='progress' failed!! 
Traceback (most recent call last):
  File "/Users/libangguo/python/project/data_canal/mysqlConnect.py", line 84, in querydata
    cursor.execute(sql)
  File "/opt/homebrew/lib/python3.11/site-packages/pymysql/cursors.py", line 148, in execute
    result = self._query(query)
             ^^^^^^^^^^^^^^^^^^
  File "/opt/homebrew/lib/python3.11/site-packages/pymysql/cursors.py", line 310, in _query
    conn.query(q)
  File "/opt/homebrew/lib/python3.11/site-packages/pymysql/connections.py", line 548, in query
    self._affected_rows = self._read_query_result(unbuffered=unbuffered)
                          ^^^^^^^^^^^^^^^^^^^^^^^^^^^^^^^^^^^^^^^^^^^^^^
  File "/opt/homebrew/lib/python3.11/site-packages/pymysql/connections.py", line 775, in _read_query_result
    result.read()
  File "/opt/homebrew/lib/python3.11/site-packages/pymysql/connections.py", line 1156, in read
    first_packet = self.connection._read_packet()
                   ^^^^^^^^^^^^^^^^^^^^^^^^^^^^^^
  File "/opt/homebrew/lib/python3.11/site-packages/pymysql/connections.py", line 725, in _read_packet
    packet.raise_for_error()
  File "/opt/homebrew/lib/python3.11/site-packages/pymysql/protocol.py", line 221, in raise_for_error
    err.raise_mysql_exception(self._data)
  File "/opt/homebrew/lib/python3.11/site-packages/pymysql/err.py", line 143, in raise_mysql_exception
    raise errorclass(errno, errval)
pymysql.err.ProgrammingError: (1146, "Table 'data_canal.task1' doesn't exist")
 
[2023-03-21 00:35:37] [ERROR] failed to get task, error:error! 127.0.0.1 - 3306: select select * from task1 where name like '%xxx%' failed!! 
Traceback (most recent call last):
  File "/Users/libangguo/python/project/data_canal/mysqlConnect.py", line 84, in querydata
    cursor.execute(sql)
  File "/opt/homebrew/lib/python3.11/site-packages/pymysql/cursors.py", line 148, in execute
    result = self._query(query)
             ^^^^^^^^^^^^^^^^^^
  File "/opt/homebrew/lib/python3.11/site-packages/pymysql/cursors.py", line 310, in _query
    conn.query(q)
  File "/opt/homebrew/lib/python3.11/site-packages/pymysql/connections.py", line 548, in query
    self._affected_rows = self._read_query_result(unbuffered=unbuffered)
                          ^^^^^^^^^^^^^^^^^^^^^^^^^^^^^^^^^^^^^^^^^^^^^^
  File "/opt/homebrew/lib/python3.11/site-packages/pymysql/connections.py", line 775, in _read_query_result
    result.read()
  File "/opt/homebrew/lib/python3.11/site-packages/pymysql/connections.py", line 1156, in read
    first_packet = self.connection._read_packet()
                   ^^^^^^^^^^^^^^^^^^^^^^^^^^^^^^
  File "/opt/homebrew/lib/python3.11/site-packages/pymysql/connections.py", line 725, in _read_packet
    packet.raise_for_error()
  File "/opt/homebrew/lib/python3.11/site-packages/pymysql/protocol.py", line 221, in raise_for_error
    err.raise_mysql_exception(self._data)
  File "/opt/homebrew/lib/python3.11/site-packages/pymysql/err.py", line 143, in raise_mysql_exception
    raise errorclass(errno, errval)
pymysql.err.ProgrammingError: (1146, "Table 'data_canal.task1' doesn't exist")
 
[2023-03-21 00:35:37] [ERROR] failed to get task, error:error! 127.0.0.1 - 3306: select select * from task1 where name like '%xxx%' failed!! 
Traceback (most recent call last):
  File "/Users/libangguo/python/project/data_canal/mysqlConnect.py", line 84, in querydata
    cursor.execute(sql)
  File "/opt/homebrew/lib/python3.11/site-packages/pymysql/cursors.py", line 148, in execute
    result = self._query(query)
             ^^^^^^^^^^^^^^^^^^
  File "/opt/homebrew/lib/python3.11/site-packages/pymysql/cursors.py", line 310, in _query
    conn.query(q)
  File "/opt/homebrew/lib/python3.11/site-packages/pymysql/connections.py", line 548, in query
    self._affected_rows = self._read_query_result(unbuffered=unbuffered)
                          ^^^^^^^^^^^^^^^^^^^^^^^^^^^^^^^^^^^^^^^^^^^^^^
  File "/opt/homebrew/lib/python3.11/site-packages/pymysql/connections.py", line 775, in _read_query_result
    result.read()
  File "/opt/homebrew/lib/python3.11/site-packages/pymysql/connections.py", line 1156, in read
    first_packet = self.connection._read_packet()
                   ^^^^^^^^^^^^^^^^^^^^^^^^^^^^^^
  File "/opt/homebrew/lib/python3.11/site-packages/pymysql/connections.py", line 725, in _read_packet
    packet.raise_for_error()
  File "/opt/homebrew/lib/python3.11/site-packages/pymysql/protocol.py", line 221, in raise_for_error
    err.raise_mysql_exception(self._data)
  File "/opt/homebrew/lib/python3.11/site-packages/pymysql/err.py", line 143, in raise_mysql_exception
    raise errorclass(errno, errval)
pymysql.err.ProgrammingError: (1146, "Table 'data_canal.task1' doesn't exist")
 
[2023-03-22 00:04:51] [ERROR] taskID: 1, failed to get pdf list, error:Traceback (most recent call last):
  File "/Users/libangguo/python/project/data_canal/download.py", line 34, in get_pdf_list
    pathDir = os.listdir(pdfPath)
              ^^^^^^^^^^^^^^^^^^^
FileNotFoundError: [Errno 2] No such file or directory: 'uploadsxx/'

[2023-03-22 00:39:09] [ERROR] taskID: 1, failed to get pdf list, error:Traceback (most recent call last):
  File "/Users/libangguo/python/project/data_canal/download.py", line 34, in getPdfList
    pathDir = os.listdir(pdfPath)
              ^^^^^^^^^^^^^^^^^^^
FileNotFoundError: [Errno 2] No such file or directory: 'uploadsxx/'

[2023-03-22 00:42:59] [ERROR] failed to get task, error:error! connect 127.0.0.1 - 3306 failed!! 
Traceback (most recent call last):
  File "/Users/libangguo/python/project/data_canal/mysqlConnect.py", line 73, in querydata
    conn = pymysql.connect(**dbconfig)
           ^^^^^^^^^^^^^^^^^^^^^^^^^^^
  File "/opt/homebrew/lib/python3.11/site-packages/pymysql/connections.py", line 353, in __init__
    self.connect()
  File "/opt/homebrew/lib/python3.11/site-packages/pymysql/connections.py", line 633, in connect
    self._request_authentication()
  File "/opt/homebrew/lib/python3.11/site-packages/pymysql/connections.py", line 907, in _request_authentication
    auth_packet = self._read_packet()
                  ^^^^^^^^^^^^^^^^^^^
  File "/opt/homebrew/lib/python3.11/site-packages/pymysql/connections.py", line 725, in _read_packet
    packet.raise_for_error()
  File "/opt/homebrew/lib/python3.11/site-packages/pymysql/protocol.py", line 221, in raise_for_error
    err.raise_mysql_exception(self._data)
  File "/opt/homebrew/lib/python3.11/site-packages/pymysql/err.py", line 143, in raise_mysql_exception
    raise errorclass(errno, errval)
pymysql.err.OperationalError: (1045, "Access denied for user 'root'@'localhost' (using password: YES)")
 
[2023-03-22 00:44:54] [INFO] task 25 upload success
[2023-03-22 22:56:56] [INFO] task 25 modify success, current progress is 10.
[2023-03-22 22:57:35] [INFO] task 25 modify success, current progress is 100.
[2023-03-22 22:57:35] [INFO] task 25 modify success, current progress is 100.
[2023-03-22 22:58:11] [INFO] task 25 modify success, current progress is 100.
[2023-03-22 22:58:37] [INFO] task 25 modify success, current progress is 0.
[2023-03-22 22:58:37] [INFO] task 25 modify success, current progress is 0.
[2023-03-22 23:00:35] [ERROR] taskID: 25, failed to modify task, error:error! exec failed!! 
Traceback (most recent call last):
  File "/Users/libangguo/python/project/data_canal/mysqlConnect.py", line 119, in queryUpdate
    cursor.execute(sql)
  File "/opt/homebrew/lib/python3.11/site-packages/pymysql/cursors.py", line 148, in execute
    result = self._query(query)
             ^^^^^^^^^^^^^^^^^^
  File "/opt/homebrew/lib/python3.11/site-packages/pymysql/cursors.py", line 310, in _query
    conn.query(q)
  File "/opt/homebrew/lib/python3.11/site-packages/pymysql/connections.py", line 548, in query
    self._affected_rows = self._read_query_result(unbuffered=unbuffered)
                          ^^^^^^^^^^^^^^^^^^^^^^^^^^^^^^^^^^^^^^^^^^^^^^
  File "/opt/homebrew/lib/python3.11/site-packages/pymysql/connections.py", line 775, in _read_query_result
    result.read()
  File "/opt/homebrew/lib/python3.11/site-packages/pymysql/connections.py", line 1156, in read
    first_packet = self.connection._read_packet()
                   ^^^^^^^^^^^^^^^^^^^^^^^^^^^^^^
  File "/opt/homebrew/lib/python3.11/site-packages/pymysql/connections.py", line 725, in _read_packet
    packet.raise_for_error()
  File "/opt/homebrew/lib/python3.11/site-packages/pymysql/protocol.py", line 221, in raise_for_error
    err.raise_mysql_exception(self._data)
  File "/opt/homebrew/lib/python3.11/site-packages/pymysql/err.py", line 143, in raise_mysql_exception
    raise errorclass(errno, errval)
pymysql.err.ProgrammingError: (1064, "You have an error in your SQL syntax; check the manual that corresponds to your MySQL server version for the right syntax to use near 'status='progress' where id=25' at line 1")

[2023-03-22 23:01:47] [INFO] task 25 modify success, current progress is 0.
[2023-03-22 23:02:03] [INFO] task 25 modify success, current progress is 100.
[2023-03-22 23:02:03] [INFO] task 25 modify success, current progress is 100.
[2023-03-22 23:05:47] [ERROR] taskID: 25, failed to modify task, error:error! exec failed!! 
Traceback (most recent call last):
  File "/Users/libangguo/python/project/data_canal/mysqlConnect.py", line 119, in queryUpdate
    cursor.execute(sql)
  File "/opt/homebrew/lib/python3.11/site-packages/pymysql/cursors.py", line 148, in execute
    result = self._query(query)
             ^^^^^^^^^^^^^^^^^^
  File "/opt/homebrew/lib/python3.11/site-packages/pymysql/cursors.py", line 310, in _query
    conn.query(q)
  File "/opt/homebrew/lib/python3.11/site-packages/pymysql/connections.py", line 548, in query
    self._affected_rows = self._read_query_result(unbuffered=unbuffered)
                          ^^^^^^^^^^^^^^^^^^^^^^^^^^^^^^^^^^^^^^^^^^^^^^
  File "/opt/homebrew/lib/python3.11/site-packages/pymysql/connections.py", line 775, in _read_query_result
    result.read()
  File "/opt/homebrew/lib/python3.11/site-packages/pymysql/connections.py", line 1156, in read
    first_packet = self.connection._read_packet()
                   ^^^^^^^^^^^^^^^^^^^^^^^^^^^^^^
  File "/opt/homebrew/lib/python3.11/site-packages/pymysql/connections.py", line 725, in _read_packet
    packet.raise_for_error()
  File "/opt/homebrew/lib/python3.11/site-packages/pymysql/protocol.py", line 221, in raise_for_error
    err.raise_mysql_exception(self._data)
  File "/opt/homebrew/lib/python3.11/site-packages/pymysql/err.py", line 143, in raise_mysql_exception
    raise errorclass(errno, errval)
pymysql.err.OperationalError: (1054, "Unknown column 'idq' in 'where clause'")

[2023-03-22 23:21:01] [INFO] task 29 upload success
[2023-03-22 23:22:01] [INFO] task 30 upload success
[2023-03-22 23:22:43] [INFO] task 31 upload success
[2023-03-22 23:32:18] [INFO] task 35 upload success
[2023-03-22 23:34:38] [INFO] task 36 upload success
[2023-03-22 23:35:34] [INFO] task 37 upload success
[2023-03-22 23:36:13] [INFO] task 38 upload success
[2023-03-22 23:37:50] [INFO] task 39 upload success
[2023-03-22 23:41:21] [INFO] task 41 upload success
[2023-03-22 23:43:36] [INFO] task 42 upload success
[2023-03-22 23:44:28] [INFO] task 43 upload success
[2023-03-22 23:47:04] [INFO] task 44 upload success
[2023-03-22 23:49:04] [INFO] task 45 upload success
[2023-03-22 23:50:12] [INFO] task 46 upload success
[2023-03-22 23:50:52] [ERROR] taskID: 47, failed to send info to core, error:code is not 0, failed to receive info
[2023-03-22 23:51:07] [INFO] task 48 upload success
[2023-03-22 23:56:08] [INFO] task 49 upload success
[2023-03-22 23:56:52] [INFO] task 50 upload success
[2023-03-23 00:03:43] [INFO] task 53 upload success
[2023-03-23 00:04:30] [INFO] task 54 upload success
[2023-03-23 00:46:18] [ERROR] failed to get task, error:error! 127.0.0.1 - 3306: select select * from task where status='None' where name like '%None%' failed!! 
Traceback (most recent call last):
  File "/Users/libangguo/python/project/data_canal/mysqlConnect.py", line 80, in querydata
    cursor.execute(sql)
  File "/opt/homebrew/lib/python3.11/site-packages/pymysql/cursors.py", line 148, in execute
    result = self._query(query)
             ^^^^^^^^^^^^^^^^^^
  File "/opt/homebrew/lib/python3.11/site-packages/pymysql/cursors.py", line 310, in _query
    conn.query(q)
  File "/opt/homebrew/lib/python3.11/site-packages/pymysql/connections.py", line 548, in query
    self._affected_rows = self._read_query_result(unbuffered=unbuffered)
                          ^^^^^^^^^^^^^^^^^^^^^^^^^^^^^^^^^^^^^^^^^^^^^^
  File "/opt/homebrew/lib/python3.11/site-packages/pymysql/connections.py", line 775, in _read_query_result
    result.read()
  File "/opt/homebrew/lib/python3.11/site-packages/pymysql/connections.py", line 1156, in read
    first_packet = self.connection._read_packet()
                   ^^^^^^^^^^^^^^^^^^^^^^^^^^^^^^
  File "/opt/homebrew/lib/python3.11/site-packages/pymysql/connections.py", line 725, in _read_packet
    packet.raise_for_error()
  File "/opt/homebrew/lib/python3.11/site-packages/pymysql/protocol.py", line 221, in raise_for_error
    err.raise_mysql_exception(self._data)
  File "/opt/homebrew/lib/python3.11/site-packages/pymysql/err.py", line 143, in raise_mysql_exception
    raise errorclass(errno, errval)
pymysql.err.ProgrammingError: (1064, "You have an error in your SQL syntax; check the manual that corresponds to your MySQL server version for the right syntax to use near 'where name like '%None%'' at line 1")
 
[2023-03-23 00:46:18] [ERROR] failed to get task, error:error! 127.0.0.1 - 3306: select select * from task where status='None' where name like '%None%' failed!! 
Traceback (most recent call last):
  File "/Users/libangguo/python/project/data_canal/mysqlConnect.py", line 80, in querydata
    cursor.execute(sql)
  File "/opt/homebrew/lib/python3.11/site-packages/pymysql/cursors.py", line 148, in execute
    result = self._query(query)
             ^^^^^^^^^^^^^^^^^^
  File "/opt/homebrew/lib/python3.11/site-packages/pymysql/cursors.py", line 310, in _query
    conn.query(q)
  File "/opt/homebrew/lib/python3.11/site-packages/pymysql/connections.py", line 548, in query
    self._affected_rows = self._read_query_result(unbuffered=unbuffered)
                          ^^^^^^^^^^^^^^^^^^^^^^^^^^^^^^^^^^^^^^^^^^^^^^
  File "/opt/homebrew/lib/python3.11/site-packages/pymysql/connections.py", line 775, in _read_query_result
    result.read()
  File "/opt/homebrew/lib/python3.11/site-packages/pymysql/connections.py", line 1156, in read
    first_packet = self.connection._read_packet()
                   ^^^^^^^^^^^^^^^^^^^^^^^^^^^^^^
  File "/opt/homebrew/lib/python3.11/site-packages/pymysql/connections.py", line 725, in _read_packet
    packet.raise_for_error()
  File "/opt/homebrew/lib/python3.11/site-packages/pymysql/protocol.py", line 221, in raise_for_error
    err.raise_mysql_exception(self._data)
  File "/opt/homebrew/lib/python3.11/site-packages/pymysql/err.py", line 143, in raise_mysql_exception
    raise errorclass(errno, errval)
pymysql.err.ProgrammingError: (1064, "You have an error in your SQL syntax; check the manual that corresponds to your MySQL server version for the right syntax to use near 'where name like '%None%'' at line 1")
 
[2023-03-23 00:46:19] [ERROR] failed to get task, error:error! 127.0.0.1 - 3306: select select * from task where status='None' where name like '%None%' failed!! 
Traceback (most recent call last):
  File "/Users/libangguo/python/project/data_canal/mysqlConnect.py", line 80, in querydata
    cursor.execute(sql)
  File "/opt/homebrew/lib/python3.11/site-packages/pymysql/cursors.py", line 148, in execute
    result = self._query(query)
             ^^^^^^^^^^^^^^^^^^
  File "/opt/homebrew/lib/python3.11/site-packages/pymysql/cursors.py", line 310, in _query
    conn.query(q)
  File "/opt/homebrew/lib/python3.11/site-packages/pymysql/connections.py", line 548, in query
    self._affected_rows = self._read_query_result(unbuffered=unbuffered)
                          ^^^^^^^^^^^^^^^^^^^^^^^^^^^^^^^^^^^^^^^^^^^^^^
  File "/opt/homebrew/lib/python3.11/site-packages/pymysql/connections.py", line 775, in _read_query_result
    result.read()
  File "/opt/homebrew/lib/python3.11/site-packages/pymysql/connections.py", line 1156, in read
    first_packet = self.connection._read_packet()
                   ^^^^^^^^^^^^^^^^^^^^^^^^^^^^^^
  File "/opt/homebrew/lib/python3.11/site-packages/pymysql/connections.py", line 725, in _read_packet
    packet.raise_for_error()
  File "/opt/homebrew/lib/python3.11/site-packages/pymysql/protocol.py", line 221, in raise_for_error
    err.raise_mysql_exception(self._data)
  File "/opt/homebrew/lib/python3.11/site-packages/pymysql/err.py", line 143, in raise_mysql_exception
    raise errorclass(errno, errval)
pymysql.err.ProgrammingError: (1064, "You have an error in your SQL syntax; check the manual that corresponds to your MySQL server version for the right syntax to use near 'where name like '%None%'' at line 1")
 
[2023-03-23 00:46:19] [ERROR] failed to get task, error:error! 127.0.0.1 - 3306: select select * from task where status='None' where name like '%None%' failed!! 
Traceback (most recent call last):
  File "/Users/libangguo/python/project/data_canal/mysqlConnect.py", line 80, in querydata
    cursor.execute(sql)
  File "/opt/homebrew/lib/python3.11/site-packages/pymysql/cursors.py", line 148, in execute
    result = self._query(query)
             ^^^^^^^^^^^^^^^^^^
  File "/opt/homebrew/lib/python3.11/site-packages/pymysql/cursors.py", line 310, in _query
    conn.query(q)
  File "/opt/homebrew/lib/python3.11/site-packages/pymysql/connections.py", line 548, in query
    self._affected_rows = self._read_query_result(unbuffered=unbuffered)
                          ^^^^^^^^^^^^^^^^^^^^^^^^^^^^^^^^^^^^^^^^^^^^^^
  File "/opt/homebrew/lib/python3.11/site-packages/pymysql/connections.py", line 775, in _read_query_result
    result.read()
  File "/opt/homebrew/lib/python3.11/site-packages/pymysql/connections.py", line 1156, in read
    first_packet = self.connection._read_packet()
                   ^^^^^^^^^^^^^^^^^^^^^^^^^^^^^^
  File "/opt/homebrew/lib/python3.11/site-packages/pymysql/connections.py", line 725, in _read_packet
    packet.raise_for_error()
  File "/opt/homebrew/lib/python3.11/site-packages/pymysql/protocol.py", line 221, in raise_for_error
    err.raise_mysql_exception(self._data)
  File "/opt/homebrew/lib/python3.11/site-packages/pymysql/err.py", line 143, in raise_mysql_exception
    raise errorclass(errno, errval)
pymysql.err.ProgrammingError: (1064, "You have an error in your SQL syntax; check the manual that corresponds to your MySQL server version for the right syntax to use near 'where name like '%None%'' at line 1")
 
[2023-03-23 00:46:19] [ERROR] failed to get task, error:error! 127.0.0.1 - 3306: select select * from task where status='None' where name like '%None%' failed!! 
Traceback (most recent call last):
  File "/Users/libangguo/python/project/data_canal/mysqlConnect.py", line 80, in querydata
    cursor.execute(sql)
  File "/opt/homebrew/lib/python3.11/site-packages/pymysql/cursors.py", line 148, in execute
    result = self._query(query)
             ^^^^^^^^^^^^^^^^^^
  File "/opt/homebrew/lib/python3.11/site-packages/pymysql/cursors.py", line 310, in _query
    conn.query(q)
  File "/opt/homebrew/lib/python3.11/site-packages/pymysql/connections.py", line 548, in query
    self._affected_rows = self._read_query_result(unbuffered=unbuffered)
                          ^^^^^^^^^^^^^^^^^^^^^^^^^^^^^^^^^^^^^^^^^^^^^^
  File "/opt/homebrew/lib/python3.11/site-packages/pymysql/connections.py", line 775, in _read_query_result
    result.read()
  File "/opt/homebrew/lib/python3.11/site-packages/pymysql/connections.py", line 1156, in read
    first_packet = self.connection._read_packet()
                   ^^^^^^^^^^^^^^^^^^^^^^^^^^^^^^
  File "/opt/homebrew/lib/python3.11/site-packages/pymysql/connections.py", line 725, in _read_packet
    packet.raise_for_error()
  File "/opt/homebrew/lib/python3.11/site-packages/pymysql/protocol.py", line 221, in raise_for_error
    err.raise_mysql_exception(self._data)
  File "/opt/homebrew/lib/python3.11/site-packages/pymysql/err.py", line 143, in raise_mysql_exception
    raise errorclass(errno, errval)
pymysql.err.ProgrammingError: (1064, "You have an error in your SQL syntax; check the manual that corresponds to your MySQL server version for the right syntax to use near 'where name like '%None%'' at line 1")
 
[2023-03-23 00:46:23] [ERROR] failed to get task, error:error! 127.0.0.1 - 3306: select select * from task where status='None' where name like '%None%' failed!! 
Traceback (most recent call last):
  File "/Users/libangguo/python/project/data_canal/mysqlConnect.py", line 80, in querydata
    cursor.execute(sql)
  File "/opt/homebrew/lib/python3.11/site-packages/pymysql/cursors.py", line 148, in execute
    result = self._query(query)
             ^^^^^^^^^^^^^^^^^^
  File "/opt/homebrew/lib/python3.11/site-packages/pymysql/cursors.py", line 310, in _query
    conn.query(q)
  File "/opt/homebrew/lib/python3.11/site-packages/pymysql/connections.py", line 548, in query
    self._affected_rows = self._read_query_result(unbuffered=unbuffered)
                          ^^^^^^^^^^^^^^^^^^^^^^^^^^^^^^^^^^^^^^^^^^^^^^
  File "/opt/homebrew/lib/python3.11/site-packages/pymysql/connections.py", line 775, in _read_query_result
    result.read()
  File "/opt/homebrew/lib/python3.11/site-packages/pymysql/connections.py", line 1156, in read
    first_packet = self.connection._read_packet()
                   ^^^^^^^^^^^^^^^^^^^^^^^^^^^^^^
  File "/opt/homebrew/lib/python3.11/site-packages/pymysql/connections.py", line 725, in _read_packet
    packet.raise_for_error()
  File "/opt/homebrew/lib/python3.11/site-packages/pymysql/protocol.py", line 221, in raise_for_error
    err.raise_mysql_exception(self._data)
  File "/opt/homebrew/lib/python3.11/site-packages/pymysql/err.py", line 143, in raise_mysql_exception
    raise errorclass(errno, errval)
pymysql.err.ProgrammingError: (1064, "You have an error in your SQL syntax; check the manual that corresponds to your MySQL server version for the right syntax to use near 'where name like '%None%'' at line 1")
 
[2023-03-23 00:46:23] [ERROR] failed to get task, error:error! 127.0.0.1 - 3306: select select * from task where status='None' where name like '%None%' failed!! 
Traceback (most recent call last):
  File "/Users/libangguo/python/project/data_canal/mysqlConnect.py", line 80, in querydata
    cursor.execute(sql)
  File "/opt/homebrew/lib/python3.11/site-packages/pymysql/cursors.py", line 148, in execute
    result = self._query(query)
             ^^^^^^^^^^^^^^^^^^
  File "/opt/homebrew/lib/python3.11/site-packages/pymysql/cursors.py", line 310, in _query
    conn.query(q)
  File "/opt/homebrew/lib/python3.11/site-packages/pymysql/connections.py", line 548, in query
    self._affected_rows = self._read_query_result(unbuffered=unbuffered)
                          ^^^^^^^^^^^^^^^^^^^^^^^^^^^^^^^^^^^^^^^^^^^^^^
  File "/opt/homebrew/lib/python3.11/site-packages/pymysql/connections.py", line 775, in _read_query_result
    result.read()
  File "/opt/homebrew/lib/python3.11/site-packages/pymysql/connections.py", line 1156, in read
    first_packet = self.connection._read_packet()
                   ^^^^^^^^^^^^^^^^^^^^^^^^^^^^^^
  File "/opt/homebrew/lib/python3.11/site-packages/pymysql/connections.py", line 725, in _read_packet
    packet.raise_for_error()
  File "/opt/homebrew/lib/python3.11/site-packages/pymysql/protocol.py", line 221, in raise_for_error
    err.raise_mysql_exception(self._data)
  File "/opt/homebrew/lib/python3.11/site-packages/pymysql/err.py", line 143, in raise_mysql_exception
    raise errorclass(errno, errval)
pymysql.err.ProgrammingError: (1064, "You have an error in your SQL syntax; check the manual that corresponds to your MySQL server version for the right syntax to use near 'where name like '%None%'' at line 1")
 
[2023-03-23 00:46:23] [ERROR] failed to get task, error:error! 127.0.0.1 - 3306: select select * from task where status='None' where name like '%None%' failed!! 
Traceback (most recent call last):
  File "/Users/libangguo/python/project/data_canal/mysqlConnect.py", line 80, in querydata
    cursor.execute(sql)
  File "/opt/homebrew/lib/python3.11/site-packages/pymysql/cursors.py", line 148, in execute
    result = self._query(query)
             ^^^^^^^^^^^^^^^^^^
  File "/opt/homebrew/lib/python3.11/site-packages/pymysql/cursors.py", line 310, in _query
    conn.query(q)
  File "/opt/homebrew/lib/python3.11/site-packages/pymysql/connections.py", line 548, in query
    self._affected_rows = self._read_query_result(unbuffered=unbuffered)
                          ^^^^^^^^^^^^^^^^^^^^^^^^^^^^^^^^^^^^^^^^^^^^^^
  File "/opt/homebrew/lib/python3.11/site-packages/pymysql/connections.py", line 775, in _read_query_result
    result.read()
  File "/opt/homebrew/lib/python3.11/site-packages/pymysql/connections.py", line 1156, in read
    first_packet = self.connection._read_packet()
                   ^^^^^^^^^^^^^^^^^^^^^^^^^^^^^^
  File "/opt/homebrew/lib/python3.11/site-packages/pymysql/connections.py", line 725, in _read_packet
    packet.raise_for_error()
  File "/opt/homebrew/lib/python3.11/site-packages/pymysql/protocol.py", line 221, in raise_for_error
    err.raise_mysql_exception(self._data)
  File "/opt/homebrew/lib/python3.11/site-packages/pymysql/err.py", line 143, in raise_mysql_exception
    raise errorclass(errno, errval)
pymysql.err.ProgrammingError: (1064, "You have an error in your SQL syntax; check the manual that corresponds to your MySQL server version for the right syntax to use near 'where name like '%None%'' at line 1")
 
[2023-03-23 00:46:23] [ERROR] failed to get task, error:error! 127.0.0.1 - 3306: select select * from task where status='None' where name like '%None%' failed!! 
Traceback (most recent call last):
  File "/Users/libangguo/python/project/data_canal/mysqlConnect.py", line 80, in querydata
    cursor.execute(sql)
  File "/opt/homebrew/lib/python3.11/site-packages/pymysql/cursors.py", line 148, in execute
    result = self._query(query)
             ^^^^^^^^^^^^^^^^^^
  File "/opt/homebrew/lib/python3.11/site-packages/pymysql/cursors.py", line 310, in _query
    conn.query(q)
  File "/opt/homebrew/lib/python3.11/site-packages/pymysql/connections.py", line 548, in query
    self._affected_rows = self._read_query_result(unbuffered=unbuffered)
                          ^^^^^^^^^^^^^^^^^^^^^^^^^^^^^^^^^^^^^^^^^^^^^^
  File "/opt/homebrew/lib/python3.11/site-packages/pymysql/connections.py", line 775, in _read_query_result
    result.read()
  File "/opt/homebrew/lib/python3.11/site-packages/pymysql/connections.py", line 1156, in read
    first_packet = self.connection._read_packet()
                   ^^^^^^^^^^^^^^^^^^^^^^^^^^^^^^
  File "/opt/homebrew/lib/python3.11/site-packages/pymysql/connections.py", line 725, in _read_packet
    packet.raise_for_error()
  File "/opt/homebrew/lib/python3.11/site-packages/pymysql/protocol.py", line 221, in raise_for_error
    err.raise_mysql_exception(self._data)
  File "/opt/homebrew/lib/python3.11/site-packages/pymysql/err.py", line 143, in raise_mysql_exception
    raise errorclass(errno, errval)
pymysql.err.ProgrammingError: (1064, "You have an error in your SQL syntax; check the manual that corresponds to your MySQL server version for the right syntax to use near 'where name like '%None%'' at line 1")
 
[2023-03-23 00:47:24] [ERROR] failed to get task, error:error! 127.0.0.1 - 3306: select select * from task where status='None' where name like '%None%' failed!! 
Traceback (most recent call last):
  File "/Users/libangguo/python/project/data_canal/mysqlConnect.py", line 80, in querydata
    cursor.execute(sql)
  File "/opt/homebrew/lib/python3.11/site-packages/pymysql/cursors.py", line 148, in execute
    result = self._query(query)
             ^^^^^^^^^^^^^^^^^^
  File "/opt/homebrew/lib/python3.11/site-packages/pymysql/cursors.py", line 310, in _query
    conn.query(q)
  File "/opt/homebrew/lib/python3.11/site-packages/pymysql/connections.py", line 548, in query
    self._affected_rows = self._read_query_result(unbuffered=unbuffered)
                          ^^^^^^^^^^^^^^^^^^^^^^^^^^^^^^^^^^^^^^^^^^^^^^
  File "/opt/homebrew/lib/python3.11/site-packages/pymysql/connections.py", line 775, in _read_query_result
    result.read()
  File "/opt/homebrew/lib/python3.11/site-packages/pymysql/connections.py", line 1156, in read
    first_packet = self.connection._read_packet()
                   ^^^^^^^^^^^^^^^^^^^^^^^^^^^^^^
  File "/opt/homebrew/lib/python3.11/site-packages/pymysql/connections.py", line 725, in _read_packet
    packet.raise_for_error()
  File "/opt/homebrew/lib/python3.11/site-packages/pymysql/protocol.py", line 221, in raise_for_error
    err.raise_mysql_exception(self._data)
  File "/opt/homebrew/lib/python3.11/site-packages/pymysql/err.py", line 143, in raise_mysql_exception
    raise errorclass(errno, errval)
pymysql.err.ProgrammingError: (1064, "You have an error in your SQL syntax; check the manual that corresponds to your MySQL server version for the right syntax to use near 'where name like '%None%'' at line 1")
 
[2023-03-23 00:47:24] [ERROR] failed to get task, error:error! 127.0.0.1 - 3306: select select * from task where status='None' where name like '%None%' failed!! 
Traceback (most recent call last):
  File "/Users/libangguo/python/project/data_canal/mysqlConnect.py", line 80, in querydata
    cursor.execute(sql)
  File "/opt/homebrew/lib/python3.11/site-packages/pymysql/cursors.py", line 148, in execute
    result = self._query(query)
             ^^^^^^^^^^^^^^^^^^
  File "/opt/homebrew/lib/python3.11/site-packages/pymysql/cursors.py", line 310, in _query
    conn.query(q)
  File "/opt/homebrew/lib/python3.11/site-packages/pymysql/connections.py", line 548, in query
    self._affected_rows = self._read_query_result(unbuffered=unbuffered)
                          ^^^^^^^^^^^^^^^^^^^^^^^^^^^^^^^^^^^^^^^^^^^^^^
  File "/opt/homebrew/lib/python3.11/site-packages/pymysql/connections.py", line 775, in _read_query_result
    result.read()
  File "/opt/homebrew/lib/python3.11/site-packages/pymysql/connections.py", line 1156, in read
    first_packet = self.connection._read_packet()
                   ^^^^^^^^^^^^^^^^^^^^^^^^^^^^^^
  File "/opt/homebrew/lib/python3.11/site-packages/pymysql/connections.py", line 725, in _read_packet
    packet.raise_for_error()
  File "/opt/homebrew/lib/python3.11/site-packages/pymysql/protocol.py", line 221, in raise_for_error
    err.raise_mysql_exception(self._data)
  File "/opt/homebrew/lib/python3.11/site-packages/pymysql/err.py", line 143, in raise_mysql_exception
    raise errorclass(errno, errval)
pymysql.err.ProgrammingError: (1064, "You have an error in your SQL syntax; check the manual that corresponds to your MySQL server version for the right syntax to use near 'where name like '%None%'' at line 1")
 
[2023-03-23 00:47:24] [ERROR] failed to get task, error:error! 127.0.0.1 - 3306: select select * from task where status='None' where name like '%None%' failed!! 
Traceback (most recent call last):
  File "/Users/libangguo/python/project/data_canal/mysqlConnect.py", line 80, in querydata
    cursor.execute(sql)
  File "/opt/homebrew/lib/python3.11/site-packages/pymysql/cursors.py", line 148, in execute
    result = self._query(query)
             ^^^^^^^^^^^^^^^^^^
  File "/opt/homebrew/lib/python3.11/site-packages/pymysql/cursors.py", line 310, in _query
    conn.query(q)
  File "/opt/homebrew/lib/python3.11/site-packages/pymysql/connections.py", line 548, in query
    self._affected_rows = self._read_query_result(unbuffered=unbuffered)
                          ^^^^^^^^^^^^^^^^^^^^^^^^^^^^^^^^^^^^^^^^^^^^^^
  File "/opt/homebrew/lib/python3.11/site-packages/pymysql/connections.py", line 775, in _read_query_result
    result.read()
  File "/opt/homebrew/lib/python3.11/site-packages/pymysql/connections.py", line 1156, in read
    first_packet = self.connection._read_packet()
                   ^^^^^^^^^^^^^^^^^^^^^^^^^^^^^^
  File "/opt/homebrew/lib/python3.11/site-packages/pymysql/connections.py", line 725, in _read_packet
    packet.raise_for_error()
  File "/opt/homebrew/lib/python3.11/site-packages/pymysql/protocol.py", line 221, in raise_for_error
    err.raise_mysql_exception(self._data)
  File "/opt/homebrew/lib/python3.11/site-packages/pymysql/err.py", line 143, in raise_mysql_exception
    raise errorclass(errno, errval)
pymysql.err.ProgrammingError: (1064, "You have an error in your SQL syntax; check the manual that corresponds to your MySQL server version for the right syntax to use near 'where name like '%None%'' at line 1")
 
[2023-03-23 00:47:24] [ERROR] failed to get task, error:error! 127.0.0.1 - 3306: select select * from task where status='None' where name like '%None%' failed!! 
Traceback (most recent call last):
  File "/Users/libangguo/python/project/data_canal/mysqlConnect.py", line 80, in querydata
    cursor.execute(sql)
  File "/opt/homebrew/lib/python3.11/site-packages/pymysql/cursors.py", line 148, in execute
    result = self._query(query)
             ^^^^^^^^^^^^^^^^^^
  File "/opt/homebrew/lib/python3.11/site-packages/pymysql/cursors.py", line 310, in _query
    conn.query(q)
  File "/opt/homebrew/lib/python3.11/site-packages/pymysql/connections.py", line 548, in query
    self._affected_rows = self._read_query_result(unbuffered=unbuffered)
                          ^^^^^^^^^^^^^^^^^^^^^^^^^^^^^^^^^^^^^^^^^^^^^^
  File "/opt/homebrew/lib/python3.11/site-packages/pymysql/connections.py", line 775, in _read_query_result
    result.read()
  File "/opt/homebrew/lib/python3.11/site-packages/pymysql/connections.py", line 1156, in read
    first_packet = self.connection._read_packet()
                   ^^^^^^^^^^^^^^^^^^^^^^^^^^^^^^
  File "/opt/homebrew/lib/python3.11/site-packages/pymysql/connections.py", line 725, in _read_packet
    packet.raise_for_error()
  File "/opt/homebrew/lib/python3.11/site-packages/pymysql/protocol.py", line 221, in raise_for_error
    err.raise_mysql_exception(self._data)
  File "/opt/homebrew/lib/python3.11/site-packages/pymysql/err.py", line 143, in raise_mysql_exception
    raise errorclass(errno, errval)
pymysql.err.ProgrammingError: (1064, "You have an error in your SQL syntax; check the manual that corresponds to your MySQL server version for the right syntax to use near 'where name like '%None%'' at line 1")
 
[2023-03-23 00:47:24] [ERROR] failed to get task, error:error! 127.0.0.1 - 3306: select select * from task where status='None' where name like '%None%' failed!! 
Traceback (most recent call last):
  File "/Users/libangguo/python/project/data_canal/mysqlConnect.py", line 80, in querydata
    cursor.execute(sql)
  File "/opt/homebrew/lib/python3.11/site-packages/pymysql/cursors.py", line 148, in execute
    result = self._query(query)
             ^^^^^^^^^^^^^^^^^^
  File "/opt/homebrew/lib/python3.11/site-packages/pymysql/cursors.py", line 310, in _query
    conn.query(q)
  File "/opt/homebrew/lib/python3.11/site-packages/pymysql/connections.py", line 548, in query
    self._affected_rows = self._read_query_result(unbuffered=unbuffered)
                          ^^^^^^^^^^^^^^^^^^^^^^^^^^^^^^^^^^^^^^^^^^^^^^
  File "/opt/homebrew/lib/python3.11/site-packages/pymysql/connections.py", line 775, in _read_query_result
    result.read()
  File "/opt/homebrew/lib/python3.11/site-packages/pymysql/connections.py", line 1156, in read
    first_packet = self.connection._read_packet()
                   ^^^^^^^^^^^^^^^^^^^^^^^^^^^^^^
  File "/opt/homebrew/lib/python3.11/site-packages/pymysql/connections.py", line 725, in _read_packet
    packet.raise_for_error()
  File "/opt/homebrew/lib/python3.11/site-packages/pymysql/protocol.py", line 221, in raise_for_error
    err.raise_mysql_exception(self._data)
  File "/opt/homebrew/lib/python3.11/site-packages/pymysql/err.py", line 143, in raise_mysql_exception
    raise errorclass(errno, errval)
pymysql.err.ProgrammingError: (1064, "You have an error in your SQL syntax; check the manual that corresponds to your MySQL server version for the right syntax to use near 'where name like '%None%'' at line 1")
 
[2023-03-23 00:47:59] [ERROR] failed to get task, error:error! 127.0.0.1 - 3306: select select * from task where status='None' where name like '%None%' failed!! 
Traceback (most recent call last):
  File "/Users/libangguo/python/project/data_canal/mysqlConnect.py", line 80, in querydata
    cursor.execute(sql)
  File "/opt/homebrew/lib/python3.11/site-packages/pymysql/cursors.py", line 148, in execute
    result = self._query(query)
             ^^^^^^^^^^^^^^^^^^
  File "/opt/homebrew/lib/python3.11/site-packages/pymysql/cursors.py", line 310, in _query
    conn.query(q)
  File "/opt/homebrew/lib/python3.11/site-packages/pymysql/connections.py", line 548, in query
    self._affected_rows = self._read_query_result(unbuffered=unbuffered)
                          ^^^^^^^^^^^^^^^^^^^^^^^^^^^^^^^^^^^^^^^^^^^^^^
  File "/opt/homebrew/lib/python3.11/site-packages/pymysql/connections.py", line 775, in _read_query_result
    result.read()
  File "/opt/homebrew/lib/python3.11/site-packages/pymysql/connections.py", line 1156, in read
    first_packet = self.connection._read_packet()
                   ^^^^^^^^^^^^^^^^^^^^^^^^^^^^^^
  File "/opt/homebrew/lib/python3.11/site-packages/pymysql/connections.py", line 725, in _read_packet
    packet.raise_for_error()
  File "/opt/homebrew/lib/python3.11/site-packages/pymysql/protocol.py", line 221, in raise_for_error
    err.raise_mysql_exception(self._data)
  File "/opt/homebrew/lib/python3.11/site-packages/pymysql/err.py", line 143, in raise_mysql_exception
    raise errorclass(errno, errval)
pymysql.err.ProgrammingError: (1064, "You have an error in your SQL syntax; check the manual that corresponds to your MySQL server version for the right syntax to use near 'where name like '%None%'' at line 1")
 
[2023-03-23 00:47:59] [ERROR] failed to get task, error:error! 127.0.0.1 - 3306: select select * from task where status='None' where name like '%None%' failed!! 
Traceback (most recent call last):
  File "/Users/libangguo/python/project/data_canal/mysqlConnect.py", line 80, in querydata
    cursor.execute(sql)
  File "/opt/homebrew/lib/python3.11/site-packages/pymysql/cursors.py", line 148, in execute
    result = self._query(query)
             ^^^^^^^^^^^^^^^^^^
  File "/opt/homebrew/lib/python3.11/site-packages/pymysql/cursors.py", line 310, in _query
    conn.query(q)
  File "/opt/homebrew/lib/python3.11/site-packages/pymysql/connections.py", line 548, in query
    self._affected_rows = self._read_query_result(unbuffered=unbuffered)
                          ^^^^^^^^^^^^^^^^^^^^^^^^^^^^^^^^^^^^^^^^^^^^^^
  File "/opt/homebrew/lib/python3.11/site-packages/pymysql/connections.py", line 775, in _read_query_result
    result.read()
  File "/opt/homebrew/lib/python3.11/site-packages/pymysql/connections.py", line 1156, in read
    first_packet = self.connection._read_packet()
                   ^^^^^^^^^^^^^^^^^^^^^^^^^^^^^^
  File "/opt/homebrew/lib/python3.11/site-packages/pymysql/connections.py", line 725, in _read_packet
    packet.raise_for_error()
  File "/opt/homebrew/lib/python3.11/site-packages/pymysql/protocol.py", line 221, in raise_for_error
    err.raise_mysql_exception(self._data)
  File "/opt/homebrew/lib/python3.11/site-packages/pymysql/err.py", line 143, in raise_mysql_exception
    raise errorclass(errno, errval)
pymysql.err.ProgrammingError: (1064, "You have an error in your SQL syntax; check the manual that corresponds to your MySQL server version for the right syntax to use near 'where name like '%None%'' at line 1")
 
[2023-03-23 00:47:59] [ERROR] failed to get task, error:error! 127.0.0.1 - 3306: select select * from task where status='None' where name like '%None%' failed!! 
Traceback (most recent call last):
  File "/Users/libangguo/python/project/data_canal/mysqlConnect.py", line 80, in querydata
    cursor.execute(sql)
  File "/opt/homebrew/lib/python3.11/site-packages/pymysql/cursors.py", line 148, in execute
    result = self._query(query)
             ^^^^^^^^^^^^^^^^^^
  File "/opt/homebrew/lib/python3.11/site-packages/pymysql/cursors.py", line 310, in _query
    conn.query(q)
  File "/opt/homebrew/lib/python3.11/site-packages/pymysql/connections.py", line 548, in query
    self._affected_rows = self._read_query_result(unbuffered=unbuffered)
                          ^^^^^^^^^^^^^^^^^^^^^^^^^^^^^^^^^^^^^^^^^^^^^^
  File "/opt/homebrew/lib/python3.11/site-packages/pymysql/connections.py", line 775, in _read_query_result
    result.read()
  File "/opt/homebrew/lib/python3.11/site-packages/pymysql/connections.py", line 1156, in read
    first_packet = self.connection._read_packet()
                   ^^^^^^^^^^^^^^^^^^^^^^^^^^^^^^
  File "/opt/homebrew/lib/python3.11/site-packages/pymysql/connections.py", line 725, in _read_packet
    packet.raise_for_error()
  File "/opt/homebrew/lib/python3.11/site-packages/pymysql/protocol.py", line 221, in raise_for_error
    err.raise_mysql_exception(self._data)
  File "/opt/homebrew/lib/python3.11/site-packages/pymysql/err.py", line 143, in raise_mysql_exception
    raise errorclass(errno, errval)
pymysql.err.ProgrammingError: (1064, "You have an error in your SQL syntax; check the manual that corresponds to your MySQL server version for the right syntax to use near 'where name like '%None%'' at line 1")
 
[2023-03-23 00:47:59] [ERROR] failed to get task, error:error! 127.0.0.1 - 3306: select select * from task where status='None' where name like '%None%' failed!! 
Traceback (most recent call last):
  File "/Users/libangguo/python/project/data_canal/mysqlConnect.py", line 80, in querydata
    cursor.execute(sql)
  File "/opt/homebrew/lib/python3.11/site-packages/pymysql/cursors.py", line 148, in execute
    result = self._query(query)
             ^^^^^^^^^^^^^^^^^^
  File "/opt/homebrew/lib/python3.11/site-packages/pymysql/cursors.py", line 310, in _query
    conn.query(q)
  File "/opt/homebrew/lib/python3.11/site-packages/pymysql/connections.py", line 548, in query
    self._affected_rows = self._read_query_result(unbuffered=unbuffered)
                          ^^^^^^^^^^^^^^^^^^^^^^^^^^^^^^^^^^^^^^^^^^^^^^
  File "/opt/homebrew/lib/python3.11/site-packages/pymysql/connections.py", line 775, in _read_query_result
    result.read()
  File "/opt/homebrew/lib/python3.11/site-packages/pymysql/connections.py", line 1156, in read
    first_packet = self.connection._read_packet()
                   ^^^^^^^^^^^^^^^^^^^^^^^^^^^^^^
  File "/opt/homebrew/lib/python3.11/site-packages/pymysql/connections.py", line 725, in _read_packet
    packet.raise_for_error()
  File "/opt/homebrew/lib/python3.11/site-packages/pymysql/protocol.py", line 221, in raise_for_error
    err.raise_mysql_exception(self._data)
  File "/opt/homebrew/lib/python3.11/site-packages/pymysql/err.py", line 143, in raise_mysql_exception
    raise errorclass(errno, errval)
pymysql.err.ProgrammingError: (1064, "You have an error in your SQL syntax; check the manual that corresponds to your MySQL server version for the right syntax to use near 'where name like '%None%'' at line 1")
 
[2023-03-23 00:47:59] [ERROR] failed to get task, error:error! 127.0.0.1 - 3306: select select * from task where status='None' where name like '%None%' failed!! 
Traceback (most recent call last):
  File "/Users/libangguo/python/project/data_canal/mysqlConnect.py", line 80, in querydata
    cursor.execute(sql)
  File "/opt/homebrew/lib/python3.11/site-packages/pymysql/cursors.py", line 148, in execute
    result = self._query(query)
             ^^^^^^^^^^^^^^^^^^
  File "/opt/homebrew/lib/python3.11/site-packages/pymysql/cursors.py", line 310, in _query
    conn.query(q)
  File "/opt/homebrew/lib/python3.11/site-packages/pymysql/connections.py", line 548, in query
    self._affected_rows = self._read_query_result(unbuffered=unbuffered)
                          ^^^^^^^^^^^^^^^^^^^^^^^^^^^^^^^^^^^^^^^^^^^^^^
  File "/opt/homebrew/lib/python3.11/site-packages/pymysql/connections.py", line 775, in _read_query_result
    result.read()
  File "/opt/homebrew/lib/python3.11/site-packages/pymysql/connections.py", line 1156, in read
    first_packet = self.connection._read_packet()
                   ^^^^^^^^^^^^^^^^^^^^^^^^^^^^^^
  File "/opt/homebrew/lib/python3.11/site-packages/pymysql/connections.py", line 725, in _read_packet
    packet.raise_for_error()
  File "/opt/homebrew/lib/python3.11/site-packages/pymysql/protocol.py", line 221, in raise_for_error
    err.raise_mysql_exception(self._data)
  File "/opt/homebrew/lib/python3.11/site-packages/pymysql/err.py", line 143, in raise_mysql_exception
    raise errorclass(errno, errval)
pymysql.err.ProgrammingError: (1064, "You have an error in your SQL syntax; check the manual that corresponds to your MySQL server version for the right syntax to use near 'where name like '%None%'' at line 1")
 
[2023-03-23 00:47:59] [ERROR] failed to get task, error:error! 127.0.0.1 - 3306: select select * from task where status='None' where name like '%None%' failed!! 
Traceback (most recent call last):
  File "/Users/libangguo/python/project/data_canal/mysqlConnect.py", line 80, in querydata
    cursor.execute(sql)
  File "/opt/homebrew/lib/python3.11/site-packages/pymysql/cursors.py", line 148, in execute
    result = self._query(query)
             ^^^^^^^^^^^^^^^^^^
  File "/opt/homebrew/lib/python3.11/site-packages/pymysql/cursors.py", line 310, in _query
    conn.query(q)
  File "/opt/homebrew/lib/python3.11/site-packages/pymysql/connections.py", line 548, in query
    self._affected_rows = self._read_query_result(unbuffered=unbuffered)
                          ^^^^^^^^^^^^^^^^^^^^^^^^^^^^^^^^^^^^^^^^^^^^^^
  File "/opt/homebrew/lib/python3.11/site-packages/pymysql/connections.py", line 775, in _read_query_result
    result.read()
  File "/opt/homebrew/lib/python3.11/site-packages/pymysql/connections.py", line 1156, in read
    first_packet = self.connection._read_packet()
                   ^^^^^^^^^^^^^^^^^^^^^^^^^^^^^^
  File "/opt/homebrew/lib/python3.11/site-packages/pymysql/connections.py", line 725, in _read_packet
    packet.raise_for_error()
  File "/opt/homebrew/lib/python3.11/site-packages/pymysql/protocol.py", line 221, in raise_for_error
    err.raise_mysql_exception(self._data)
  File "/opt/homebrew/lib/python3.11/site-packages/pymysql/err.py", line 143, in raise_mysql_exception
    raise errorclass(errno, errval)
pymysql.err.ProgrammingError: (1064, "You have an error in your SQL syntax; check the manual that corresponds to your MySQL server version for the right syntax to use near 'where name like '%None%'' at line 1")
 
[2023-03-23 00:47:59] [ERROR] failed to get task, error:error! 127.0.0.1 - 3306: select select * from task where status='None' where name like '%None%' failed!! 
Traceback (most recent call last):
  File "/Users/libangguo/python/project/data_canal/mysqlConnect.py", line 80, in querydata
    cursor.execute(sql)
  File "/opt/homebrew/lib/python3.11/site-packages/pymysql/cursors.py", line 148, in execute
    result = self._query(query)
             ^^^^^^^^^^^^^^^^^^
  File "/opt/homebrew/lib/python3.11/site-packages/pymysql/cursors.py", line 310, in _query
    conn.query(q)
  File "/opt/homebrew/lib/python3.11/site-packages/pymysql/connections.py", line 548, in query
    self._affected_rows = self._read_query_result(unbuffered=unbuffered)
                          ^^^^^^^^^^^^^^^^^^^^^^^^^^^^^^^^^^^^^^^^^^^^^^
  File "/opt/homebrew/lib/python3.11/site-packages/pymysql/connections.py", line 775, in _read_query_result
    result.read()
  File "/opt/homebrew/lib/python3.11/site-packages/pymysql/connections.py", line 1156, in read
    first_packet = self.connection._read_packet()
                   ^^^^^^^^^^^^^^^^^^^^^^^^^^^^^^
  File "/opt/homebrew/lib/python3.11/site-packages/pymysql/connections.py", line 725, in _read_packet
    packet.raise_for_error()
  File "/opt/homebrew/lib/python3.11/site-packages/pymysql/protocol.py", line 221, in raise_for_error
    err.raise_mysql_exception(self._data)
  File "/opt/homebrew/lib/python3.11/site-packages/pymysql/err.py", line 143, in raise_mysql_exception
    raise errorclass(errno, errval)
pymysql.err.ProgrammingError: (1064, "You have an error in your SQL syntax; check the manual that corresponds to your MySQL server version for the right syntax to use near 'where name like '%None%'' at line 1")
 
[2023-03-23 00:48:32] [ERROR] failed to get task, error:error! 127.0.0.1 - 3306: select select * from task where status='None' where name like '%None%' failed!! 
Traceback (most recent call last):
  File "/Users/libangguo/python/project/data_canal/mysqlConnect.py", line 80, in querydata
    cursor.execute(sql)
  File "/opt/homebrew/lib/python3.11/site-packages/pymysql/cursors.py", line 148, in execute
    result = self._query(query)
             ^^^^^^^^^^^^^^^^^^
  File "/opt/homebrew/lib/python3.11/site-packages/pymysql/cursors.py", line 310, in _query
    conn.query(q)
  File "/opt/homebrew/lib/python3.11/site-packages/pymysql/connections.py", line 548, in query
    self._affected_rows = self._read_query_result(unbuffered=unbuffered)
                          ^^^^^^^^^^^^^^^^^^^^^^^^^^^^^^^^^^^^^^^^^^^^^^
  File "/opt/homebrew/lib/python3.11/site-packages/pymysql/connections.py", line 775, in _read_query_result
    result.read()
  File "/opt/homebrew/lib/python3.11/site-packages/pymysql/connections.py", line 1156, in read
    first_packet = self.connection._read_packet()
                   ^^^^^^^^^^^^^^^^^^^^^^^^^^^^^^
  File "/opt/homebrew/lib/python3.11/site-packages/pymysql/connections.py", line 725, in _read_packet
    packet.raise_for_error()
  File "/opt/homebrew/lib/python3.11/site-packages/pymysql/protocol.py", line 221, in raise_for_error
    err.raise_mysql_exception(self._data)
  File "/opt/homebrew/lib/python3.11/site-packages/pymysql/err.py", line 143, in raise_mysql_exception
    raise errorclass(errno, errval)
pymysql.err.ProgrammingError: (1064, "You have an error in your SQL syntax; check the manual that corresponds to your MySQL server version for the right syntax to use near 'where name like '%None%'' at line 1")
 
[2023-03-23 00:48:32] [ERROR] failed to get task, error:error! 127.0.0.1 - 3306: select select * from task where status='None' where name like '%None%' failed!! 
Traceback (most recent call last):
  File "/Users/libangguo/python/project/data_canal/mysqlConnect.py", line 80, in querydata
    cursor.execute(sql)
  File "/opt/homebrew/lib/python3.11/site-packages/pymysql/cursors.py", line 148, in execute
    result = self._query(query)
             ^^^^^^^^^^^^^^^^^^
  File "/opt/homebrew/lib/python3.11/site-packages/pymysql/cursors.py", line 310, in _query
    conn.query(q)
  File "/opt/homebrew/lib/python3.11/site-packages/pymysql/connections.py", line 548, in query
    self._affected_rows = self._read_query_result(unbuffered=unbuffered)
                          ^^^^^^^^^^^^^^^^^^^^^^^^^^^^^^^^^^^^^^^^^^^^^^
  File "/opt/homebrew/lib/python3.11/site-packages/pymysql/connections.py", line 775, in _read_query_result
    result.read()
  File "/opt/homebrew/lib/python3.11/site-packages/pymysql/connections.py", line 1156, in read
    first_packet = self.connection._read_packet()
                   ^^^^^^^^^^^^^^^^^^^^^^^^^^^^^^
  File "/opt/homebrew/lib/python3.11/site-packages/pymysql/connections.py", line 725, in _read_packet
    packet.raise_for_error()
  File "/opt/homebrew/lib/python3.11/site-packages/pymysql/protocol.py", line 221, in raise_for_error
    err.raise_mysql_exception(self._data)
  File "/opt/homebrew/lib/python3.11/site-packages/pymysql/err.py", line 143, in raise_mysql_exception
    raise errorclass(errno, errval)
pymysql.err.ProgrammingError: (1064, "You have an error in your SQL syntax; check the manual that corresponds to your MySQL server version for the right syntax to use near 'where name like '%None%'' at line 1")
 
[2023-03-23 00:48:32] [ERROR] failed to get task, error:error! 127.0.0.1 - 3306: select select * from task where status='None' where name like '%None%' failed!! 
Traceback (most recent call last):
  File "/Users/libangguo/python/project/data_canal/mysqlConnect.py", line 80, in querydata
    cursor.execute(sql)
  File "/opt/homebrew/lib/python3.11/site-packages/pymysql/cursors.py", line 148, in execute
    result = self._query(query)
             ^^^^^^^^^^^^^^^^^^
  File "/opt/homebrew/lib/python3.11/site-packages/pymysql/cursors.py", line 310, in _query
    conn.query(q)
  File "/opt/homebrew/lib/python3.11/site-packages/pymysql/connections.py", line 548, in query
    self._affected_rows = self._read_query_result(unbuffered=unbuffered)
                          ^^^^^^^^^^^^^^^^^^^^^^^^^^^^^^^^^^^^^^^^^^^^^^
  File "/opt/homebrew/lib/python3.11/site-packages/pymysql/connections.py", line 775, in _read_query_result
    result.read()
  File "/opt/homebrew/lib/python3.11/site-packages/pymysql/connections.py", line 1156, in read
    first_packet = self.connection._read_packet()
                   ^^^^^^^^^^^^^^^^^^^^^^^^^^^^^^
  File "/opt/homebrew/lib/python3.11/site-packages/pymysql/connections.py", line 725, in _read_packet
    packet.raise_for_error()
  File "/opt/homebrew/lib/python3.11/site-packages/pymysql/protocol.py", line 221, in raise_for_error
    err.raise_mysql_exception(self._data)
  File "/opt/homebrew/lib/python3.11/site-packages/pymysql/err.py", line 143, in raise_mysql_exception
    raise errorclass(errno, errval)
pymysql.err.ProgrammingError: (1064, "You have an error in your SQL syntax; check the manual that corresponds to your MySQL server version for the right syntax to use near 'where name like '%None%'' at line 1")
 
[2023-03-23 00:48:32] [ERROR] failed to get task, error:error! 127.0.0.1 - 3306: select select * from task where status='None' where name like '%None%' failed!! 
Traceback (most recent call last):
  File "/Users/libangguo/python/project/data_canal/mysqlConnect.py", line 80, in querydata
    cursor.execute(sql)
  File "/opt/homebrew/lib/python3.11/site-packages/pymysql/cursors.py", line 148, in execute
    result = self._query(query)
             ^^^^^^^^^^^^^^^^^^
  File "/opt/homebrew/lib/python3.11/site-packages/pymysql/cursors.py", line 310, in _query
    conn.query(q)
  File "/opt/homebrew/lib/python3.11/site-packages/pymysql/connections.py", line 548, in query
    self._affected_rows = self._read_query_result(unbuffered=unbuffered)
                          ^^^^^^^^^^^^^^^^^^^^^^^^^^^^^^^^^^^^^^^^^^^^^^
  File "/opt/homebrew/lib/python3.11/site-packages/pymysql/connections.py", line 775, in _read_query_result
    result.read()
  File "/opt/homebrew/lib/python3.11/site-packages/pymysql/connections.py", line 1156, in read
    first_packet = self.connection._read_packet()
                   ^^^^^^^^^^^^^^^^^^^^^^^^^^^^^^
  File "/opt/homebrew/lib/python3.11/site-packages/pymysql/connections.py", line 725, in _read_packet
    packet.raise_for_error()
  File "/opt/homebrew/lib/python3.11/site-packages/pymysql/protocol.py", line 221, in raise_for_error
    err.raise_mysql_exception(self._data)
  File "/opt/homebrew/lib/python3.11/site-packages/pymysql/err.py", line 143, in raise_mysql_exception
    raise errorclass(errno, errval)
pymysql.err.ProgrammingError: (1064, "You have an error in your SQL syntax; check the manual that corresponds to your MySQL server version for the right syntax to use near 'where name like '%None%'' at line 1")
 
[2023-03-23 00:48:32] [ERROR] failed to get task, error:error! 127.0.0.1 - 3306: select select * from task where status='None' where name like '%None%' failed!! 
Traceback (most recent call last):
  File "/Users/libangguo/python/project/data_canal/mysqlConnect.py", line 80, in querydata
    cursor.execute(sql)
  File "/opt/homebrew/lib/python3.11/site-packages/pymysql/cursors.py", line 148, in execute
    result = self._query(query)
             ^^^^^^^^^^^^^^^^^^
  File "/opt/homebrew/lib/python3.11/site-packages/pymysql/cursors.py", line 310, in _query
    conn.query(q)
  File "/opt/homebrew/lib/python3.11/site-packages/pymysql/connections.py", line 548, in query
    self._affected_rows = self._read_query_result(unbuffered=unbuffered)
                          ^^^^^^^^^^^^^^^^^^^^^^^^^^^^^^^^^^^^^^^^^^^^^^
  File "/opt/homebrew/lib/python3.11/site-packages/pymysql/connections.py", line 775, in _read_query_result
    result.read()
  File "/opt/homebrew/lib/python3.11/site-packages/pymysql/connections.py", line 1156, in read
    first_packet = self.connection._read_packet()
                   ^^^^^^^^^^^^^^^^^^^^^^^^^^^^^^
  File "/opt/homebrew/lib/python3.11/site-packages/pymysql/connections.py", line 725, in _read_packet
    packet.raise_for_error()
  File "/opt/homebrew/lib/python3.11/site-packages/pymysql/protocol.py", line 221, in raise_for_error
    err.raise_mysql_exception(self._data)
  File "/opt/homebrew/lib/python3.11/site-packages/pymysql/err.py", line 143, in raise_mysql_exception
    raise errorclass(errno, errval)
pymysql.err.ProgrammingError: (1064, "You have an error in your SQL syntax; check the manual that corresponds to your MySQL server version for the right syntax to use near 'where name like '%None%'' at line 1")
 
[2023-03-23 00:48:32] [ERROR] failed to get task, error:error! 127.0.0.1 - 3306: select select * from task where status='None' where name like '%None%' failed!! 
Traceback (most recent call last):
  File "/Users/libangguo/python/project/data_canal/mysqlConnect.py", line 80, in querydata
    cursor.execute(sql)
  File "/opt/homebrew/lib/python3.11/site-packages/pymysql/cursors.py", line 148, in execute
    result = self._query(query)
             ^^^^^^^^^^^^^^^^^^
  File "/opt/homebrew/lib/python3.11/site-packages/pymysql/cursors.py", line 310, in _query
    conn.query(q)
  File "/opt/homebrew/lib/python3.11/site-packages/pymysql/connections.py", line 548, in query
    self._affected_rows = self._read_query_result(unbuffered=unbuffered)
                          ^^^^^^^^^^^^^^^^^^^^^^^^^^^^^^^^^^^^^^^^^^^^^^
  File "/opt/homebrew/lib/python3.11/site-packages/pymysql/connections.py", line 775, in _read_query_result
    result.read()
  File "/opt/homebrew/lib/python3.11/site-packages/pymysql/connections.py", line 1156, in read
    first_packet = self.connection._read_packet()
                   ^^^^^^^^^^^^^^^^^^^^^^^^^^^^^^
  File "/opt/homebrew/lib/python3.11/site-packages/pymysql/connections.py", line 725, in _read_packet
    packet.raise_for_error()
  File "/opt/homebrew/lib/python3.11/site-packages/pymysql/protocol.py", line 221, in raise_for_error
    err.raise_mysql_exception(self._data)
  File "/opt/homebrew/lib/python3.11/site-packages/pymysql/err.py", line 143, in raise_mysql_exception
    raise errorclass(errno, errval)
pymysql.err.ProgrammingError: (1064, "You have an error in your SQL syntax; check the manual that corresponds to your MySQL server version for the right syntax to use near 'where name like '%None%'' at line 1")
 
[2023-03-23 00:48:32] [ERROR] failed to get task, error:error! 127.0.0.1 - 3306: select select * from task where status='None' where name like '%None%' failed!! 
Traceback (most recent call last):
  File "/Users/libangguo/python/project/data_canal/mysqlConnect.py", line 80, in querydata
    cursor.execute(sql)
  File "/opt/homebrew/lib/python3.11/site-packages/pymysql/cursors.py", line 148, in execute
    result = self._query(query)
             ^^^^^^^^^^^^^^^^^^
  File "/opt/homebrew/lib/python3.11/site-packages/pymysql/cursors.py", line 310, in _query
    conn.query(q)
  File "/opt/homebrew/lib/python3.11/site-packages/pymysql/connections.py", line 548, in query
    self._affected_rows = self._read_query_result(unbuffered=unbuffered)
                          ^^^^^^^^^^^^^^^^^^^^^^^^^^^^^^^^^^^^^^^^^^^^^^
  File "/opt/homebrew/lib/python3.11/site-packages/pymysql/connections.py", line 775, in _read_query_result
    result.read()
  File "/opt/homebrew/lib/python3.11/site-packages/pymysql/connections.py", line 1156, in read
    first_packet = self.connection._read_packet()
                   ^^^^^^^^^^^^^^^^^^^^^^^^^^^^^^
  File "/opt/homebrew/lib/python3.11/site-packages/pymysql/connections.py", line 725, in _read_packet
    packet.raise_for_error()
  File "/opt/homebrew/lib/python3.11/site-packages/pymysql/protocol.py", line 221, in raise_for_error
    err.raise_mysql_exception(self._data)
  File "/opt/homebrew/lib/python3.11/site-packages/pymysql/err.py", line 143, in raise_mysql_exception
    raise errorclass(errno, errval)
pymysql.err.ProgrammingError: (1064, "You have an error in your SQL syntax; check the manual that corresponds to your MySQL server version for the right syntax to use near 'where name like '%None%'' at line 1")
 
[2023-03-23 00:48:32] [ERROR] failed to get task, error:error! 127.0.0.1 - 3306: select select * from task where status='None' where name like '%None%' failed!! 
Traceback (most recent call last):
  File "/Users/libangguo/python/project/data_canal/mysqlConnect.py", line 80, in querydata
    cursor.execute(sql)
  File "/opt/homebrew/lib/python3.11/site-packages/pymysql/cursors.py", line 148, in execute
    result = self._query(query)
             ^^^^^^^^^^^^^^^^^^
  File "/opt/homebrew/lib/python3.11/site-packages/pymysql/cursors.py", line 310, in _query
    conn.query(q)
  File "/opt/homebrew/lib/python3.11/site-packages/pymysql/connections.py", line 548, in query
    self._affected_rows = self._read_query_result(unbuffered=unbuffered)
                          ^^^^^^^^^^^^^^^^^^^^^^^^^^^^^^^^^^^^^^^^^^^^^^
  File "/opt/homebrew/lib/python3.11/site-packages/pymysql/connections.py", line 775, in _read_query_result
    result.read()
  File "/opt/homebrew/lib/python3.11/site-packages/pymysql/connections.py", line 1156, in read
    first_packet = self.connection._read_packet()
                   ^^^^^^^^^^^^^^^^^^^^^^^^^^^^^^
  File "/opt/homebrew/lib/python3.11/site-packages/pymysql/connections.py", line 725, in _read_packet
    packet.raise_for_error()
  File "/opt/homebrew/lib/python3.11/site-packages/pymysql/protocol.py", line 221, in raise_for_error
    err.raise_mysql_exception(self._data)
  File "/opt/homebrew/lib/python3.11/site-packages/pymysql/err.py", line 143, in raise_mysql_exception
    raise errorclass(errno, errval)
pymysql.err.ProgrammingError: (1064, "You have an error in your SQL syntax; check the manual that corresponds to your MySQL server version for the right syntax to use near 'where name like '%None%'' at line 1")
 
[2023-03-23 00:48:57] [ERROR] failed to get task, error:error! 127.0.0.1 - 3306: select select * from task where status='None' where name like '%None%' failed!! 
Traceback (most recent call last):
  File "/Users/libangguo/python/project/data_canal/mysqlConnect.py", line 80, in querydata
    cursor.execute(sql)
  File "/opt/homebrew/lib/python3.11/site-packages/pymysql/cursors.py", line 148, in execute
    result = self._query(query)
             ^^^^^^^^^^^^^^^^^^
  File "/opt/homebrew/lib/python3.11/site-packages/pymysql/cursors.py", line 310, in _query
    conn.query(q)
  File "/opt/homebrew/lib/python3.11/site-packages/pymysql/connections.py", line 548, in query
    self._affected_rows = self._read_query_result(unbuffered=unbuffered)
                          ^^^^^^^^^^^^^^^^^^^^^^^^^^^^^^^^^^^^^^^^^^^^^^
  File "/opt/homebrew/lib/python3.11/site-packages/pymysql/connections.py", line 775, in _read_query_result
    result.read()
  File "/opt/homebrew/lib/python3.11/site-packages/pymysql/connections.py", line 1156, in read
    first_packet = self.connection._read_packet()
                   ^^^^^^^^^^^^^^^^^^^^^^^^^^^^^^
  File "/opt/homebrew/lib/python3.11/site-packages/pymysql/connections.py", line 725, in _read_packet
    packet.raise_for_error()
  File "/opt/homebrew/lib/python3.11/site-packages/pymysql/protocol.py", line 221, in raise_for_error
    err.raise_mysql_exception(self._data)
  File "/opt/homebrew/lib/python3.11/site-packages/pymysql/err.py", line 143, in raise_mysql_exception
    raise errorclass(errno, errval)
pymysql.err.ProgrammingError: (1064, "You have an error in your SQL syntax; check the manual that corresponds to your MySQL server version for the right syntax to use near 'where name like '%None%'' at line 1")
 
[2023-03-23 00:48:57] [ERROR] failed to get task, error:error! 127.0.0.1 - 3306: select select * from task where status='None' where name like '%None%' failed!! 
Traceback (most recent call last):
  File "/Users/libangguo/python/project/data_canal/mysqlConnect.py", line 80, in querydata
    cursor.execute(sql)
  File "/opt/homebrew/lib/python3.11/site-packages/pymysql/cursors.py", line 148, in execute
    result = self._query(query)
             ^^^^^^^^^^^^^^^^^^
  File "/opt/homebrew/lib/python3.11/site-packages/pymysql/cursors.py", line 310, in _query
    conn.query(q)
  File "/opt/homebrew/lib/python3.11/site-packages/pymysql/connections.py", line 548, in query
    self._affected_rows = self._read_query_result(unbuffered=unbuffered)
                          ^^^^^^^^^^^^^^^^^^^^^^^^^^^^^^^^^^^^^^^^^^^^^^
  File "/opt/homebrew/lib/python3.11/site-packages/pymysql/connections.py", line 775, in _read_query_result
    result.read()
  File "/opt/homebrew/lib/python3.11/site-packages/pymysql/connections.py", line 1156, in read
    first_packet = self.connection._read_packet()
                   ^^^^^^^^^^^^^^^^^^^^^^^^^^^^^^
  File "/opt/homebrew/lib/python3.11/site-packages/pymysql/connections.py", line 725, in _read_packet
    packet.raise_for_error()
  File "/opt/homebrew/lib/python3.11/site-packages/pymysql/protocol.py", line 221, in raise_for_error
    err.raise_mysql_exception(self._data)
  File "/opt/homebrew/lib/python3.11/site-packages/pymysql/err.py", line 143, in raise_mysql_exception
    raise errorclass(errno, errval)
pymysql.err.ProgrammingError: (1064, "You have an error in your SQL syntax; check the manual that corresponds to your MySQL server version for the right syntax to use near 'where name like '%None%'' at line 1")
 
[2023-03-23 00:48:57] [ERROR] failed to get task, error:error! 127.0.0.1 - 3306: select select * from task where status='None' where name like '%None%' failed!! 
Traceback (most recent call last):
  File "/Users/libangguo/python/project/data_canal/mysqlConnect.py", line 80, in querydata
    cursor.execute(sql)
  File "/opt/homebrew/lib/python3.11/site-packages/pymysql/cursors.py", line 148, in execute
    result = self._query(query)
             ^^^^^^^^^^^^^^^^^^
  File "/opt/homebrew/lib/python3.11/site-packages/pymysql/cursors.py", line 310, in _query
    conn.query(q)
  File "/opt/homebrew/lib/python3.11/site-packages/pymysql/connections.py", line 548, in query
    self._affected_rows = self._read_query_result(unbuffered=unbuffered)
                          ^^^^^^^^^^^^^^^^^^^^^^^^^^^^^^^^^^^^^^^^^^^^^^
  File "/opt/homebrew/lib/python3.11/site-packages/pymysql/connections.py", line 775, in _read_query_result
    result.read()
  File "/opt/homebrew/lib/python3.11/site-packages/pymysql/connections.py", line 1156, in read
    first_packet = self.connection._read_packet()
                   ^^^^^^^^^^^^^^^^^^^^^^^^^^^^^^
  File "/opt/homebrew/lib/python3.11/site-packages/pymysql/connections.py", line 725, in _read_packet
    packet.raise_for_error()
  File "/opt/homebrew/lib/python3.11/site-packages/pymysql/protocol.py", line 221, in raise_for_error
    err.raise_mysql_exception(self._data)
  File "/opt/homebrew/lib/python3.11/site-packages/pymysql/err.py", line 143, in raise_mysql_exception
    raise errorclass(errno, errval)
pymysql.err.ProgrammingError: (1064, "You have an error in your SQL syntax; check the manual that corresponds to your MySQL server version for the right syntax to use near 'where name like '%None%'' at line 1")
 
[2023-03-23 00:48:57] [ERROR] failed to get task, error:error! 127.0.0.1 - 3306: select select * from task where status='None' where name like '%None%' failed!! 
Traceback (most recent call last):
  File "/Users/libangguo/python/project/data_canal/mysqlConnect.py", line 80, in querydata
    cursor.execute(sql)
  File "/opt/homebrew/lib/python3.11/site-packages/pymysql/cursors.py", line 148, in execute
    result = self._query(query)
             ^^^^^^^^^^^^^^^^^^
  File "/opt/homebrew/lib/python3.11/site-packages/pymysql/cursors.py", line 310, in _query
    conn.query(q)
  File "/opt/homebrew/lib/python3.11/site-packages/pymysql/connections.py", line 548, in query
    self._affected_rows = self._read_query_result(unbuffered=unbuffered)
                          ^^^^^^^^^^^^^^^^^^^^^^^^^^^^^^^^^^^^^^^^^^^^^^
  File "/opt/homebrew/lib/python3.11/site-packages/pymysql/connections.py", line 775, in _read_query_result
    result.read()
  File "/opt/homebrew/lib/python3.11/site-packages/pymysql/connections.py", line 1156, in read
    first_packet = self.connection._read_packet()
                   ^^^^^^^^^^^^^^^^^^^^^^^^^^^^^^
  File "/opt/homebrew/lib/python3.11/site-packages/pymysql/connections.py", line 725, in _read_packet
    packet.raise_for_error()
  File "/opt/homebrew/lib/python3.11/site-packages/pymysql/protocol.py", line 221, in raise_for_error
    err.raise_mysql_exception(self._data)
  File "/opt/homebrew/lib/python3.11/site-packages/pymysql/err.py", line 143, in raise_mysql_exception
    raise errorclass(errno, errval)
pymysql.err.ProgrammingError: (1064, "You have an error in your SQL syntax; check the manual that corresponds to your MySQL server version for the right syntax to use near 'where name like '%None%'' at line 1")
 
[2023-03-23 00:48:57] [ERROR] failed to get task, error:error! 127.0.0.1 - 3306: select select * from task where status='None' where name like '%None%' failed!! 
Traceback (most recent call last):
  File "/Users/libangguo/python/project/data_canal/mysqlConnect.py", line 80, in querydata
    cursor.execute(sql)
  File "/opt/homebrew/lib/python3.11/site-packages/pymysql/cursors.py", line 148, in execute
    result = self._query(query)
             ^^^^^^^^^^^^^^^^^^
  File "/opt/homebrew/lib/python3.11/site-packages/pymysql/cursors.py", line 310, in _query
    conn.query(q)
  File "/opt/homebrew/lib/python3.11/site-packages/pymysql/connections.py", line 548, in query
    self._affected_rows = self._read_query_result(unbuffered=unbuffered)
                          ^^^^^^^^^^^^^^^^^^^^^^^^^^^^^^^^^^^^^^^^^^^^^^
  File "/opt/homebrew/lib/python3.11/site-packages/pymysql/connections.py", line 775, in _read_query_result
    result.read()
  File "/opt/homebrew/lib/python3.11/site-packages/pymysql/connections.py", line 1156, in read
    first_packet = self.connection._read_packet()
                   ^^^^^^^^^^^^^^^^^^^^^^^^^^^^^^
  File "/opt/homebrew/lib/python3.11/site-packages/pymysql/connections.py", line 725, in _read_packet
    packet.raise_for_error()
  File "/opt/homebrew/lib/python3.11/site-packages/pymysql/protocol.py", line 221, in raise_for_error
    err.raise_mysql_exception(self._data)
  File "/opt/homebrew/lib/python3.11/site-packages/pymysql/err.py", line 143, in raise_mysql_exception
    raise errorclass(errno, errval)
pymysql.err.ProgrammingError: (1064, "You have an error in your SQL syntax; check the manual that corresponds to your MySQL server version for the right syntax to use near 'where name like '%None%'' at line 1")
 
[2023-03-23 00:48:57] [ERROR] failed to get task, error:error! 127.0.0.1 - 3306: select select * from task where status='None' where name like '%None%' failed!! 
Traceback (most recent call last):
  File "/Users/libangguo/python/project/data_canal/mysqlConnect.py", line 80, in querydata
    cursor.execute(sql)
  File "/opt/homebrew/lib/python3.11/site-packages/pymysql/cursors.py", line 148, in execute
    result = self._query(query)
             ^^^^^^^^^^^^^^^^^^
  File "/opt/homebrew/lib/python3.11/site-packages/pymysql/cursors.py", line 310, in _query
    conn.query(q)
  File "/opt/homebrew/lib/python3.11/site-packages/pymysql/connections.py", line 548, in query
    self._affected_rows = self._read_query_result(unbuffered=unbuffered)
                          ^^^^^^^^^^^^^^^^^^^^^^^^^^^^^^^^^^^^^^^^^^^^^^
  File "/opt/homebrew/lib/python3.11/site-packages/pymysql/connections.py", line 775, in _read_query_result
    result.read()
  File "/opt/homebrew/lib/python3.11/site-packages/pymysql/connections.py", line 1156, in read
    first_packet = self.connection._read_packet()
                   ^^^^^^^^^^^^^^^^^^^^^^^^^^^^^^
  File "/opt/homebrew/lib/python3.11/site-packages/pymysql/connections.py", line 725, in _read_packet
    packet.raise_for_error()
  File "/opt/homebrew/lib/python3.11/site-packages/pymysql/protocol.py", line 221, in raise_for_error
    err.raise_mysql_exception(self._data)
  File "/opt/homebrew/lib/python3.11/site-packages/pymysql/err.py", line 143, in raise_mysql_exception
    raise errorclass(errno, errval)
pymysql.err.ProgrammingError: (1064, "You have an error in your SQL syntax; check the manual that corresponds to your MySQL server version for the right syntax to use near 'where name like '%None%'' at line 1")
 
[2023-03-23 00:48:57] [ERROR] failed to get task, error:error! 127.0.0.1 - 3306: select select * from task where status='None' where name like '%None%' failed!! 
Traceback (most recent call last):
  File "/Users/libangguo/python/project/data_canal/mysqlConnect.py", line 80, in querydata
    cursor.execute(sql)
  File "/opt/homebrew/lib/python3.11/site-packages/pymysql/cursors.py", line 148, in execute
    result = self._query(query)
             ^^^^^^^^^^^^^^^^^^
  File "/opt/homebrew/lib/python3.11/site-packages/pymysql/cursors.py", line 310, in _query
    conn.query(q)
  File "/opt/homebrew/lib/python3.11/site-packages/pymysql/connections.py", line 548, in query
    self._affected_rows = self._read_query_result(unbuffered=unbuffered)
                          ^^^^^^^^^^^^^^^^^^^^^^^^^^^^^^^^^^^^^^^^^^^^^^
  File "/opt/homebrew/lib/python3.11/site-packages/pymysql/connections.py", line 775, in _read_query_result
    result.read()
  File "/opt/homebrew/lib/python3.11/site-packages/pymysql/connections.py", line 1156, in read
    first_packet = self.connection._read_packet()
                   ^^^^^^^^^^^^^^^^^^^^^^^^^^^^^^
  File "/opt/homebrew/lib/python3.11/site-packages/pymysql/connections.py", line 725, in _read_packet
    packet.raise_for_error()
  File "/opt/homebrew/lib/python3.11/site-packages/pymysql/protocol.py", line 221, in raise_for_error
    err.raise_mysql_exception(self._data)
  File "/opt/homebrew/lib/python3.11/site-packages/pymysql/err.py", line 143, in raise_mysql_exception
    raise errorclass(errno, errval)
pymysql.err.ProgrammingError: (1064, "You have an error in your SQL syntax; check the manual that corresponds to your MySQL server version for the right syntax to use near 'where name like '%None%'' at line 1")
 
[2023-03-23 00:48:57] [ERROR] failed to get task, error:error! 127.0.0.1 - 3306: select select * from task where status='None' where name like '%None%' failed!! 
Traceback (most recent call last):
  File "/Users/libangguo/python/project/data_canal/mysqlConnect.py", line 80, in querydata
    cursor.execute(sql)
  File "/opt/homebrew/lib/python3.11/site-packages/pymysql/cursors.py", line 148, in execute
    result = self._query(query)
             ^^^^^^^^^^^^^^^^^^
  File "/opt/homebrew/lib/python3.11/site-packages/pymysql/cursors.py", line 310, in _query
    conn.query(q)
  File "/opt/homebrew/lib/python3.11/site-packages/pymysql/connections.py", line 548, in query
    self._affected_rows = self._read_query_result(unbuffered=unbuffered)
                          ^^^^^^^^^^^^^^^^^^^^^^^^^^^^^^^^^^^^^^^^^^^^^^
  File "/opt/homebrew/lib/python3.11/site-packages/pymysql/connections.py", line 775, in _read_query_result
    result.read()
  File "/opt/homebrew/lib/python3.11/site-packages/pymysql/connections.py", line 1156, in read
    first_packet = self.connection._read_packet()
                   ^^^^^^^^^^^^^^^^^^^^^^^^^^^^^^
  File "/opt/homebrew/lib/python3.11/site-packages/pymysql/connections.py", line 725, in _read_packet
    packet.raise_for_error()
  File "/opt/homebrew/lib/python3.11/site-packages/pymysql/protocol.py", line 221, in raise_for_error
    err.raise_mysql_exception(self._data)
  File "/opt/homebrew/lib/python3.11/site-packages/pymysql/err.py", line 143, in raise_mysql_exception
    raise errorclass(errno, errval)
pymysql.err.ProgrammingError: (1064, "You have an error in your SQL syntax; check the manual that corresponds to your MySQL server version for the right syntax to use near 'where name like '%None%'' at line 1")
 
[2023-03-23 00:48:57] [ERROR] failed to get task, error:error! 127.0.0.1 - 3306: select select * from task where status='None' where name like '%None%' failed!! 
Traceback (most recent call last):
  File "/Users/libangguo/python/project/data_canal/mysqlConnect.py", line 80, in querydata
    cursor.execute(sql)
  File "/opt/homebrew/lib/python3.11/site-packages/pymysql/cursors.py", line 148, in execute
    result = self._query(query)
             ^^^^^^^^^^^^^^^^^^
  File "/opt/homebrew/lib/python3.11/site-packages/pymysql/cursors.py", line 310, in _query
    conn.query(q)
  File "/opt/homebrew/lib/python3.11/site-packages/pymysql/connections.py", line 548, in query
    self._affected_rows = self._read_query_result(unbuffered=unbuffered)
                          ^^^^^^^^^^^^^^^^^^^^^^^^^^^^^^^^^^^^^^^^^^^^^^
  File "/opt/homebrew/lib/python3.11/site-packages/pymysql/connections.py", line 775, in _read_query_result
    result.read()
  File "/opt/homebrew/lib/python3.11/site-packages/pymysql/connections.py", line 1156, in read
    first_packet = self.connection._read_packet()
                   ^^^^^^^^^^^^^^^^^^^^^^^^^^^^^^
  File "/opt/homebrew/lib/python3.11/site-packages/pymysql/connections.py", line 725, in _read_packet
    packet.raise_for_error()
  File "/opt/homebrew/lib/python3.11/site-packages/pymysql/protocol.py", line 221, in raise_for_error
    err.raise_mysql_exception(self._data)
  File "/opt/homebrew/lib/python3.11/site-packages/pymysql/err.py", line 143, in raise_mysql_exception
    raise errorclass(errno, errval)
pymysql.err.ProgrammingError: (1064, "You have an error in your SQL syntax; check the manual that corresponds to your MySQL server version for the right syntax to use near 'where name like '%None%'' at line 1")
 
[2023-03-23 00:49:07] [ERROR] failed to get task, error:error! 127.0.0.1 - 3306: select select * from task where status='None' where name like '%None%' failed!! 
Traceback (most recent call last):
  File "/Users/libangguo/python/project/data_canal/mysqlConnect.py", line 80, in querydata
    cursor.execute(sql)
  File "/opt/homebrew/lib/python3.11/site-packages/pymysql/cursors.py", line 148, in execute
    result = self._query(query)
             ^^^^^^^^^^^^^^^^^^
  File "/opt/homebrew/lib/python3.11/site-packages/pymysql/cursors.py", line 310, in _query
    conn.query(q)
  File "/opt/homebrew/lib/python3.11/site-packages/pymysql/connections.py", line 548, in query
    self._affected_rows = self._read_query_result(unbuffered=unbuffered)
                          ^^^^^^^^^^^^^^^^^^^^^^^^^^^^^^^^^^^^^^^^^^^^^^
  File "/opt/homebrew/lib/python3.11/site-packages/pymysql/connections.py", line 775, in _read_query_result
    result.read()
  File "/opt/homebrew/lib/python3.11/site-packages/pymysql/connections.py", line 1156, in read
    first_packet = self.connection._read_packet()
                   ^^^^^^^^^^^^^^^^^^^^^^^^^^^^^^
  File "/opt/homebrew/lib/python3.11/site-packages/pymysql/connections.py", line 725, in _read_packet
    packet.raise_for_error()
  File "/opt/homebrew/lib/python3.11/site-packages/pymysql/protocol.py", line 221, in raise_for_error
    err.raise_mysql_exception(self._data)
  File "/opt/homebrew/lib/python3.11/site-packages/pymysql/err.py", line 143, in raise_mysql_exception
    raise errorclass(errno, errval)
pymysql.err.ProgrammingError: (1064, "You have an error in your SQL syntax; check the manual that corresponds to your MySQL server version for the right syntax to use near 'where name like '%None%'' at line 1")
 
[2023-03-23 00:49:07] [ERROR] failed to get task, error:error! 127.0.0.1 - 3306: select select * from task where status='None' where name like '%None%' failed!! 
Traceback (most recent call last):
  File "/Users/libangguo/python/project/data_canal/mysqlConnect.py", line 80, in querydata
    cursor.execute(sql)
  File "/opt/homebrew/lib/python3.11/site-packages/pymysql/cursors.py", line 148, in execute
    result = self._query(query)
             ^^^^^^^^^^^^^^^^^^
  File "/opt/homebrew/lib/python3.11/site-packages/pymysql/cursors.py", line 310, in _query
    conn.query(q)
  File "/opt/homebrew/lib/python3.11/site-packages/pymysql/connections.py", line 548, in query
    self._affected_rows = self._read_query_result(unbuffered=unbuffered)
                          ^^^^^^^^^^^^^^^^^^^^^^^^^^^^^^^^^^^^^^^^^^^^^^
  File "/opt/homebrew/lib/python3.11/site-packages/pymysql/connections.py", line 775, in _read_query_result
    result.read()
  File "/opt/homebrew/lib/python3.11/site-packages/pymysql/connections.py", line 1156, in read
    first_packet = self.connection._read_packet()
                   ^^^^^^^^^^^^^^^^^^^^^^^^^^^^^^
  File "/opt/homebrew/lib/python3.11/site-packages/pymysql/connections.py", line 725, in _read_packet
    packet.raise_for_error()
  File "/opt/homebrew/lib/python3.11/site-packages/pymysql/protocol.py", line 221, in raise_for_error
    err.raise_mysql_exception(self._data)
  File "/opt/homebrew/lib/python3.11/site-packages/pymysql/err.py", line 143, in raise_mysql_exception
    raise errorclass(errno, errval)
pymysql.err.ProgrammingError: (1064, "You have an error in your SQL syntax; check the manual that corresponds to your MySQL server version for the right syntax to use near 'where name like '%None%'' at line 1")
 
[2023-03-23 00:49:07] [ERROR] failed to get task, error:error! 127.0.0.1 - 3306: select select * from task where status='None' where name like '%None%' failed!! 
Traceback (most recent call last):
  File "/Users/libangguo/python/project/data_canal/mysqlConnect.py", line 80, in querydata
    cursor.execute(sql)
  File "/opt/homebrew/lib/python3.11/site-packages/pymysql/cursors.py", line 148, in execute
    result = self._query(query)
             ^^^^^^^^^^^^^^^^^^
  File "/opt/homebrew/lib/python3.11/site-packages/pymysql/cursors.py", line 310, in _query
    conn.query(q)
  File "/opt/homebrew/lib/python3.11/site-packages/pymysql/connections.py", line 548, in query
    self._affected_rows = self._read_query_result(unbuffered=unbuffered)
                          ^^^^^^^^^^^^^^^^^^^^^^^^^^^^^^^^^^^^^^^^^^^^^^
  File "/opt/homebrew/lib/python3.11/site-packages/pymysql/connections.py", line 775, in _read_query_result
    result.read()
  File "/opt/homebrew/lib/python3.11/site-packages/pymysql/connections.py", line 1156, in read
    first_packet = self.connection._read_packet()
                   ^^^^^^^^^^^^^^^^^^^^^^^^^^^^^^
  File "/opt/homebrew/lib/python3.11/site-packages/pymysql/connections.py", line 725, in _read_packet
    packet.raise_for_error()
  File "/opt/homebrew/lib/python3.11/site-packages/pymysql/protocol.py", line 221, in raise_for_error
    err.raise_mysql_exception(self._data)
  File "/opt/homebrew/lib/python3.11/site-packages/pymysql/err.py", line 143, in raise_mysql_exception
    raise errorclass(errno, errval)
pymysql.err.ProgrammingError: (1064, "You have an error in your SQL syntax; check the manual that corresponds to your MySQL server version for the right syntax to use near 'where name like '%None%'' at line 1")
 
[2023-03-23 00:49:07] [ERROR] failed to get task, error:error! 127.0.0.1 - 3306: select select * from task where status='None' where name like '%None%' failed!! 
Traceback (most recent call last):
  File "/Users/libangguo/python/project/data_canal/mysqlConnect.py", line 80, in querydata
    cursor.execute(sql)
  File "/opt/homebrew/lib/python3.11/site-packages/pymysql/cursors.py", line 148, in execute
    result = self._query(query)
             ^^^^^^^^^^^^^^^^^^
  File "/opt/homebrew/lib/python3.11/site-packages/pymysql/cursors.py", line 310, in _query
    conn.query(q)
  File "/opt/homebrew/lib/python3.11/site-packages/pymysql/connections.py", line 548, in query
    self._affected_rows = self._read_query_result(unbuffered=unbuffered)
                          ^^^^^^^^^^^^^^^^^^^^^^^^^^^^^^^^^^^^^^^^^^^^^^
  File "/opt/homebrew/lib/python3.11/site-packages/pymysql/connections.py", line 775, in _read_query_result
    result.read()
  File "/opt/homebrew/lib/python3.11/site-packages/pymysql/connections.py", line 1156, in read
    first_packet = self.connection._read_packet()
                   ^^^^^^^^^^^^^^^^^^^^^^^^^^^^^^
  File "/opt/homebrew/lib/python3.11/site-packages/pymysql/connections.py", line 725, in _read_packet
    packet.raise_for_error()
  File "/opt/homebrew/lib/python3.11/site-packages/pymysql/protocol.py", line 221, in raise_for_error
    err.raise_mysql_exception(self._data)
  File "/opt/homebrew/lib/python3.11/site-packages/pymysql/err.py", line 143, in raise_mysql_exception
    raise errorclass(errno, errval)
pymysql.err.ProgrammingError: (1064, "You have an error in your SQL syntax; check the manual that corresponds to your MySQL server version for the right syntax to use near 'where name like '%None%'' at line 1")
 
[2023-03-23 00:49:07] [ERROR] failed to get task, error:error! 127.0.0.1 - 3306: select select * from task where status='None' where name like '%None%' failed!! 
Traceback (most recent call last):
  File "/Users/libangguo/python/project/data_canal/mysqlConnect.py", line 80, in querydata
    cursor.execute(sql)
  File "/opt/homebrew/lib/python3.11/site-packages/pymysql/cursors.py", line 148, in execute
    result = self._query(query)
             ^^^^^^^^^^^^^^^^^^
  File "/opt/homebrew/lib/python3.11/site-packages/pymysql/cursors.py", line 310, in _query
    conn.query(q)
  File "/opt/homebrew/lib/python3.11/site-packages/pymysql/connections.py", line 548, in query
    self._affected_rows = self._read_query_result(unbuffered=unbuffered)
                          ^^^^^^^^^^^^^^^^^^^^^^^^^^^^^^^^^^^^^^^^^^^^^^
  File "/opt/homebrew/lib/python3.11/site-packages/pymysql/connections.py", line 775, in _read_query_result
    result.read()
  File "/opt/homebrew/lib/python3.11/site-packages/pymysql/connections.py", line 1156, in read
    first_packet = self.connection._read_packet()
                   ^^^^^^^^^^^^^^^^^^^^^^^^^^^^^^
  File "/opt/homebrew/lib/python3.11/site-packages/pymysql/connections.py", line 725, in _read_packet
    packet.raise_for_error()
  File "/opt/homebrew/lib/python3.11/site-packages/pymysql/protocol.py", line 221, in raise_for_error
    err.raise_mysql_exception(self._data)
  File "/opt/homebrew/lib/python3.11/site-packages/pymysql/err.py", line 143, in raise_mysql_exception
    raise errorclass(errno, errval)
pymysql.err.ProgrammingError: (1064, "You have an error in your SQL syntax; check the manual that corresponds to your MySQL server version for the right syntax to use near 'where name like '%None%'' at line 1")
 
[2023-03-23 00:49:07] [ERROR] failed to get task, error:error! 127.0.0.1 - 3306: select select * from task where status='None' where name like '%None%' failed!! 
Traceback (most recent call last):
  File "/Users/libangguo/python/project/data_canal/mysqlConnect.py", line 80, in querydata
    cursor.execute(sql)
  File "/opt/homebrew/lib/python3.11/site-packages/pymysql/cursors.py", line 148, in execute
    result = self._query(query)
             ^^^^^^^^^^^^^^^^^^
  File "/opt/homebrew/lib/python3.11/site-packages/pymysql/cursors.py", line 310, in _query
    conn.query(q)
  File "/opt/homebrew/lib/python3.11/site-packages/pymysql/connections.py", line 548, in query
    self._affected_rows = self._read_query_result(unbuffered=unbuffered)
                          ^^^^^^^^^^^^^^^^^^^^^^^^^^^^^^^^^^^^^^^^^^^^^^
  File "/opt/homebrew/lib/python3.11/site-packages/pymysql/connections.py", line 775, in _read_query_result
    result.read()
  File "/opt/homebrew/lib/python3.11/site-packages/pymysql/connections.py", line 1156, in read
    first_packet = self.connection._read_packet()
                   ^^^^^^^^^^^^^^^^^^^^^^^^^^^^^^
  File "/opt/homebrew/lib/python3.11/site-packages/pymysql/connections.py", line 725, in _read_packet
    packet.raise_for_error()
  File "/opt/homebrew/lib/python3.11/site-packages/pymysql/protocol.py", line 221, in raise_for_error
    err.raise_mysql_exception(self._data)
  File "/opt/homebrew/lib/python3.11/site-packages/pymysql/err.py", line 143, in raise_mysql_exception
    raise errorclass(errno, errval)
pymysql.err.ProgrammingError: (1064, "You have an error in your SQL syntax; check the manual that corresponds to your MySQL server version for the right syntax to use near 'where name like '%None%'' at line 1")
 
[2023-03-23 00:49:07] [ERROR] failed to get task, error:error! 127.0.0.1 - 3306: select select * from task where status='None' where name like '%None%' failed!! 
Traceback (most recent call last):
  File "/Users/libangguo/python/project/data_canal/mysqlConnect.py", line 80, in querydata
    cursor.execute(sql)
  File "/opt/homebrew/lib/python3.11/site-packages/pymysql/cursors.py", line 148, in execute
    result = self._query(query)
             ^^^^^^^^^^^^^^^^^^
  File "/opt/homebrew/lib/python3.11/site-packages/pymysql/cursors.py", line 310, in _query
    conn.query(q)
  File "/opt/homebrew/lib/python3.11/site-packages/pymysql/connections.py", line 548, in query
    self._affected_rows = self._read_query_result(unbuffered=unbuffered)
                          ^^^^^^^^^^^^^^^^^^^^^^^^^^^^^^^^^^^^^^^^^^^^^^
  File "/opt/homebrew/lib/python3.11/site-packages/pymysql/connections.py", line 775, in _read_query_result
    result.read()
  File "/opt/homebrew/lib/python3.11/site-packages/pymysql/connections.py", line 1156, in read
    first_packet = self.connection._read_packet()
                   ^^^^^^^^^^^^^^^^^^^^^^^^^^^^^^
  File "/opt/homebrew/lib/python3.11/site-packages/pymysql/connections.py", line 725, in _read_packet
    packet.raise_for_error()
  File "/opt/homebrew/lib/python3.11/site-packages/pymysql/protocol.py", line 221, in raise_for_error
    err.raise_mysql_exception(self._data)
  File "/opt/homebrew/lib/python3.11/site-packages/pymysql/err.py", line 143, in raise_mysql_exception
    raise errorclass(errno, errval)
pymysql.err.ProgrammingError: (1064, "You have an error in your SQL syntax; check the manual that corresponds to your MySQL server version for the right syntax to use near 'where name like '%None%'' at line 1")
 
[2023-03-23 00:49:07] [ERROR] failed to get task, error:error! 127.0.0.1 - 3306: select select * from task where status='None' where name like '%None%' failed!! 
Traceback (most recent call last):
  File "/Users/libangguo/python/project/data_canal/mysqlConnect.py", line 80, in querydata
    cursor.execute(sql)
  File "/opt/homebrew/lib/python3.11/site-packages/pymysql/cursors.py", line 148, in execute
    result = self._query(query)
             ^^^^^^^^^^^^^^^^^^
  File "/opt/homebrew/lib/python3.11/site-packages/pymysql/cursors.py", line 310, in _query
    conn.query(q)
  File "/opt/homebrew/lib/python3.11/site-packages/pymysql/connections.py", line 548, in query
    self._affected_rows = self._read_query_result(unbuffered=unbuffered)
                          ^^^^^^^^^^^^^^^^^^^^^^^^^^^^^^^^^^^^^^^^^^^^^^
  File "/opt/homebrew/lib/python3.11/site-packages/pymysql/connections.py", line 775, in _read_query_result
    result.read()
  File "/opt/homebrew/lib/python3.11/site-packages/pymysql/connections.py", line 1156, in read
    first_packet = self.connection._read_packet()
                   ^^^^^^^^^^^^^^^^^^^^^^^^^^^^^^
  File "/opt/homebrew/lib/python3.11/site-packages/pymysql/connections.py", line 725, in _read_packet
    packet.raise_for_error()
  File "/opt/homebrew/lib/python3.11/site-packages/pymysql/protocol.py", line 221, in raise_for_error
    err.raise_mysql_exception(self._data)
  File "/opt/homebrew/lib/python3.11/site-packages/pymysql/err.py", line 143, in raise_mysql_exception
    raise errorclass(errno, errval)
pymysql.err.ProgrammingError: (1064, "You have an error in your SQL syntax; check the manual that corresponds to your MySQL server version for the right syntax to use near 'where name like '%None%'' at line 1")
 
[2023-03-23 00:49:07] [ERROR] failed to get task, error:error! 127.0.0.1 - 3306: select select * from task where status='None' where name like '%None%' failed!! 
Traceback (most recent call last):
  File "/Users/libangguo/python/project/data_canal/mysqlConnect.py", line 80, in querydata
    cursor.execute(sql)
  File "/opt/homebrew/lib/python3.11/site-packages/pymysql/cursors.py", line 148, in execute
    result = self._query(query)
             ^^^^^^^^^^^^^^^^^^
  File "/opt/homebrew/lib/python3.11/site-packages/pymysql/cursors.py", line 310, in _query
    conn.query(q)
  File "/opt/homebrew/lib/python3.11/site-packages/pymysql/connections.py", line 548, in query
    self._affected_rows = self._read_query_result(unbuffered=unbuffered)
                          ^^^^^^^^^^^^^^^^^^^^^^^^^^^^^^^^^^^^^^^^^^^^^^
  File "/opt/homebrew/lib/python3.11/site-packages/pymysql/connections.py", line 775, in _read_query_result
    result.read()
  File "/opt/homebrew/lib/python3.11/site-packages/pymysql/connections.py", line 1156, in read
    first_packet = self.connection._read_packet()
                   ^^^^^^^^^^^^^^^^^^^^^^^^^^^^^^
  File "/opt/homebrew/lib/python3.11/site-packages/pymysql/connections.py", line 725, in _read_packet
    packet.raise_for_error()
  File "/opt/homebrew/lib/python3.11/site-packages/pymysql/protocol.py", line 221, in raise_for_error
    err.raise_mysql_exception(self._data)
  File "/opt/homebrew/lib/python3.11/site-packages/pymysql/err.py", line 143, in raise_mysql_exception
    raise errorclass(errno, errval)
pymysql.err.ProgrammingError: (1064, "You have an error in your SQL syntax; check the manual that corresponds to your MySQL server version for the right syntax to use near 'where name like '%None%'' at line 1")
 
[2023-03-23 00:49:07] [ERROR] failed to get task, error:error! 127.0.0.1 - 3306: select select * from task where status='None' where name like '%None%' failed!! 
Traceback (most recent call last):
  File "/Users/libangguo/python/project/data_canal/mysqlConnect.py", line 80, in querydata
    cursor.execute(sql)
  File "/opt/homebrew/lib/python3.11/site-packages/pymysql/cursors.py", line 148, in execute
    result = self._query(query)
             ^^^^^^^^^^^^^^^^^^
  File "/opt/homebrew/lib/python3.11/site-packages/pymysql/cursors.py", line 310, in _query
    conn.query(q)
  File "/opt/homebrew/lib/python3.11/site-packages/pymysql/connections.py", line 548, in query
    self._affected_rows = self._read_query_result(unbuffered=unbuffered)
                          ^^^^^^^^^^^^^^^^^^^^^^^^^^^^^^^^^^^^^^^^^^^^^^
  File "/opt/homebrew/lib/python3.11/site-packages/pymysql/connections.py", line 775, in _read_query_result
    result.read()
  File "/opt/homebrew/lib/python3.11/site-packages/pymysql/connections.py", line 1156, in read
    first_packet = self.connection._read_packet()
                   ^^^^^^^^^^^^^^^^^^^^^^^^^^^^^^
  File "/opt/homebrew/lib/python3.11/site-packages/pymysql/connections.py", line 725, in _read_packet
    packet.raise_for_error()
  File "/opt/homebrew/lib/python3.11/site-packages/pymysql/protocol.py", line 221, in raise_for_error
    err.raise_mysql_exception(self._data)
  File "/opt/homebrew/lib/python3.11/site-packages/pymysql/err.py", line 143, in raise_mysql_exception
    raise errorclass(errno, errval)
pymysql.err.ProgrammingError: (1064, "You have an error in your SQL syntax; check the manual that corresponds to your MySQL server version for the right syntax to use near 'where name like '%None%'' at line 1")
 
[2023-03-23 00:53:02] [ERROR] failed to get task, error:error! 127.0.0.1 - 3306: select select * from task where status='None' where name like '%1%' failed!! 
Traceback (most recent call last):
  File "/Users/libangguo/python/project/data_canal/mysqlConnect.py", line 80, in querydata
    cursor.execute(sql)
  File "/opt/homebrew/lib/python3.11/site-packages/pymysql/cursors.py", line 148, in execute
    result = self._query(query)
             ^^^^^^^^^^^^^^^^^^
  File "/opt/homebrew/lib/python3.11/site-packages/pymysql/cursors.py", line 310, in _query
    conn.query(q)
  File "/opt/homebrew/lib/python3.11/site-packages/pymysql/connections.py", line 548, in query
    self._affected_rows = self._read_query_result(unbuffered=unbuffered)
                          ^^^^^^^^^^^^^^^^^^^^^^^^^^^^^^^^^^^^^^^^^^^^^^
  File "/opt/homebrew/lib/python3.11/site-packages/pymysql/connections.py", line 775, in _read_query_result
    result.read()
  File "/opt/homebrew/lib/python3.11/site-packages/pymysql/connections.py", line 1156, in read
    first_packet = self.connection._read_packet()
                   ^^^^^^^^^^^^^^^^^^^^^^^^^^^^^^
  File "/opt/homebrew/lib/python3.11/site-packages/pymysql/connections.py", line 725, in _read_packet
    packet.raise_for_error()
  File "/opt/homebrew/lib/python3.11/site-packages/pymysql/protocol.py", line 221, in raise_for_error
    err.raise_mysql_exception(self._data)
  File "/opt/homebrew/lib/python3.11/site-packages/pymysql/err.py", line 143, in raise_mysql_exception
    raise errorclass(errno, errval)
pymysql.err.ProgrammingError: (1064, "You have an error in your SQL syntax; check the manual that corresponds to your MySQL server version for the right syntax to use near 'where name like '%1%'' at line 1")
 
[2023-03-23 00:53:02] [ERROR] failed to get task, error:error! 127.0.0.1 - 3306: select select * from task where status='None' where name like '%1%' failed!! 
Traceback (most recent call last):
  File "/Users/libangguo/python/project/data_canal/mysqlConnect.py", line 80, in querydata
    cursor.execute(sql)
  File "/opt/homebrew/lib/python3.11/site-packages/pymysql/cursors.py", line 148, in execute
    result = self._query(query)
             ^^^^^^^^^^^^^^^^^^
  File "/opt/homebrew/lib/python3.11/site-packages/pymysql/cursors.py", line 310, in _query
    conn.query(q)
  File "/opt/homebrew/lib/python3.11/site-packages/pymysql/connections.py", line 548, in query
    self._affected_rows = self._read_query_result(unbuffered=unbuffered)
                          ^^^^^^^^^^^^^^^^^^^^^^^^^^^^^^^^^^^^^^^^^^^^^^
  File "/opt/homebrew/lib/python3.11/site-packages/pymysql/connections.py", line 775, in _read_query_result
    result.read()
  File "/opt/homebrew/lib/python3.11/site-packages/pymysql/connections.py", line 1156, in read
    first_packet = self.connection._read_packet()
                   ^^^^^^^^^^^^^^^^^^^^^^^^^^^^^^
  File "/opt/homebrew/lib/python3.11/site-packages/pymysql/connections.py", line 725, in _read_packet
    packet.raise_for_error()
  File "/opt/homebrew/lib/python3.11/site-packages/pymysql/protocol.py", line 221, in raise_for_error
    err.raise_mysql_exception(self._data)
  File "/opt/homebrew/lib/python3.11/site-packages/pymysql/err.py", line 143, in raise_mysql_exception
    raise errorclass(errno, errval)
pymysql.err.ProgrammingError: (1064, "You have an error in your SQL syntax; check the manual that corresponds to your MySQL server version for the right syntax to use near 'where name like '%1%'' at line 1")
 
[2023-03-23 00:53:02] [ERROR] failed to get task, error:error! 127.0.0.1 - 3306: select select * from task where status='None' where name like '%1%' failed!! 
Traceback (most recent call last):
  File "/Users/libangguo/python/project/data_canal/mysqlConnect.py", line 80, in querydata
    cursor.execute(sql)
  File "/opt/homebrew/lib/python3.11/site-packages/pymysql/cursors.py", line 148, in execute
    result = self._query(query)
             ^^^^^^^^^^^^^^^^^^
  File "/opt/homebrew/lib/python3.11/site-packages/pymysql/cursors.py", line 310, in _query
    conn.query(q)
  File "/opt/homebrew/lib/python3.11/site-packages/pymysql/connections.py", line 548, in query
    self._affected_rows = self._read_query_result(unbuffered=unbuffered)
                          ^^^^^^^^^^^^^^^^^^^^^^^^^^^^^^^^^^^^^^^^^^^^^^
  File "/opt/homebrew/lib/python3.11/site-packages/pymysql/connections.py", line 775, in _read_query_result
    result.read()
  File "/opt/homebrew/lib/python3.11/site-packages/pymysql/connections.py", line 1156, in read
    first_packet = self.connection._read_packet()
                   ^^^^^^^^^^^^^^^^^^^^^^^^^^^^^^
  File "/opt/homebrew/lib/python3.11/site-packages/pymysql/connections.py", line 725, in _read_packet
    packet.raise_for_error()
  File "/opt/homebrew/lib/python3.11/site-packages/pymysql/protocol.py", line 221, in raise_for_error
    err.raise_mysql_exception(self._data)
  File "/opt/homebrew/lib/python3.11/site-packages/pymysql/err.py", line 143, in raise_mysql_exception
    raise errorclass(errno, errval)
pymysql.err.ProgrammingError: (1064, "You have an error in your SQL syntax; check the manual that corresponds to your MySQL server version for the right syntax to use near 'where name like '%1%'' at line 1")
 
[2023-03-23 00:53:02] [ERROR] failed to get task, error:error! 127.0.0.1 - 3306: select select * from task where status='None' where name like '%1%' failed!! 
Traceback (most recent call last):
  File "/Users/libangguo/python/project/data_canal/mysqlConnect.py", line 80, in querydata
    cursor.execute(sql)
  File "/opt/homebrew/lib/python3.11/site-packages/pymysql/cursors.py", line 148, in execute
    result = self._query(query)
             ^^^^^^^^^^^^^^^^^^
  File "/opt/homebrew/lib/python3.11/site-packages/pymysql/cursors.py", line 310, in _query
    conn.query(q)
  File "/opt/homebrew/lib/python3.11/site-packages/pymysql/connections.py", line 548, in query
    self._affected_rows = self._read_query_result(unbuffered=unbuffered)
                          ^^^^^^^^^^^^^^^^^^^^^^^^^^^^^^^^^^^^^^^^^^^^^^
  File "/opt/homebrew/lib/python3.11/site-packages/pymysql/connections.py", line 775, in _read_query_result
    result.read()
  File "/opt/homebrew/lib/python3.11/site-packages/pymysql/connections.py", line 1156, in read
    first_packet = self.connection._read_packet()
                   ^^^^^^^^^^^^^^^^^^^^^^^^^^^^^^
  File "/opt/homebrew/lib/python3.11/site-packages/pymysql/connections.py", line 725, in _read_packet
    packet.raise_for_error()
  File "/opt/homebrew/lib/python3.11/site-packages/pymysql/protocol.py", line 221, in raise_for_error
    err.raise_mysql_exception(self._data)
  File "/opt/homebrew/lib/python3.11/site-packages/pymysql/err.py", line 143, in raise_mysql_exception
    raise errorclass(errno, errval)
pymysql.err.ProgrammingError: (1064, "You have an error in your SQL syntax; check the manual that corresponds to your MySQL server version for the right syntax to use near 'where name like '%1%'' at line 1")
 
[2023-03-23 00:53:02] [ERROR] failed to get task, error:error! 127.0.0.1 - 3306: select select * from task where status='None' where name like '%1%' failed!! 
Traceback (most recent call last):
  File "/Users/libangguo/python/project/data_canal/mysqlConnect.py", line 80, in querydata
    cursor.execute(sql)
  File "/opt/homebrew/lib/python3.11/site-packages/pymysql/cursors.py", line 148, in execute
    result = self._query(query)
             ^^^^^^^^^^^^^^^^^^
  File "/opt/homebrew/lib/python3.11/site-packages/pymysql/cursors.py", line 310, in _query
    conn.query(q)
  File "/opt/homebrew/lib/python3.11/site-packages/pymysql/connections.py", line 548, in query
    self._affected_rows = self._read_query_result(unbuffered=unbuffered)
                          ^^^^^^^^^^^^^^^^^^^^^^^^^^^^^^^^^^^^^^^^^^^^^^
  File "/opt/homebrew/lib/python3.11/site-packages/pymysql/connections.py", line 775, in _read_query_result
    result.read()
  File "/opt/homebrew/lib/python3.11/site-packages/pymysql/connections.py", line 1156, in read
    first_packet = self.connection._read_packet()
                   ^^^^^^^^^^^^^^^^^^^^^^^^^^^^^^
  File "/opt/homebrew/lib/python3.11/site-packages/pymysql/connections.py", line 725, in _read_packet
    packet.raise_for_error()
  File "/opt/homebrew/lib/python3.11/site-packages/pymysql/protocol.py", line 221, in raise_for_error
    err.raise_mysql_exception(self._data)
  File "/opt/homebrew/lib/python3.11/site-packages/pymysql/err.py", line 143, in raise_mysql_exception
    raise errorclass(errno, errval)
pymysql.err.ProgrammingError: (1064, "You have an error in your SQL syntax; check the manual that corresponds to your MySQL server version for the right syntax to use near 'where name like '%1%'' at line 1")
 
[2023-03-23 00:53:02] [ERROR] failed to get task, error:error! 127.0.0.1 - 3306: select select * from task where status='None' where name like '%1%' failed!! 
Traceback (most recent call last):
  File "/Users/libangguo/python/project/data_canal/mysqlConnect.py", line 80, in querydata
    cursor.execute(sql)
  File "/opt/homebrew/lib/python3.11/site-packages/pymysql/cursors.py", line 148, in execute
    result = self._query(query)
             ^^^^^^^^^^^^^^^^^^
  File "/opt/homebrew/lib/python3.11/site-packages/pymysql/cursors.py", line 310, in _query
    conn.query(q)
  File "/opt/homebrew/lib/python3.11/site-packages/pymysql/connections.py", line 548, in query
    self._affected_rows = self._read_query_result(unbuffered=unbuffered)
                          ^^^^^^^^^^^^^^^^^^^^^^^^^^^^^^^^^^^^^^^^^^^^^^
  File "/opt/homebrew/lib/python3.11/site-packages/pymysql/connections.py", line 775, in _read_query_result
    result.read()
  File "/opt/homebrew/lib/python3.11/site-packages/pymysql/connections.py", line 1156, in read
    first_packet = self.connection._read_packet()
                   ^^^^^^^^^^^^^^^^^^^^^^^^^^^^^^
  File "/opt/homebrew/lib/python3.11/site-packages/pymysql/connections.py", line 725, in _read_packet
    packet.raise_for_error()
  File "/opt/homebrew/lib/python3.11/site-packages/pymysql/protocol.py", line 221, in raise_for_error
    err.raise_mysql_exception(self._data)
  File "/opt/homebrew/lib/python3.11/site-packages/pymysql/err.py", line 143, in raise_mysql_exception
    raise errorclass(errno, errval)
pymysql.err.ProgrammingError: (1064, "You have an error in your SQL syntax; check the manual that corresponds to your MySQL server version for the right syntax to use near 'where name like '%1%'' at line 1")
 
[2023-03-23 00:53:02] [ERROR] failed to get task, error:error! 127.0.0.1 - 3306: select select * from task where status='None' where name like '%1%' failed!! 
Traceback (most recent call last):
  File "/Users/libangguo/python/project/data_canal/mysqlConnect.py", line 80, in querydata
    cursor.execute(sql)
  File "/opt/homebrew/lib/python3.11/site-packages/pymysql/cursors.py", line 148, in execute
    result = self._query(query)
             ^^^^^^^^^^^^^^^^^^
  File "/opt/homebrew/lib/python3.11/site-packages/pymysql/cursors.py", line 310, in _query
    conn.query(q)
  File "/opt/homebrew/lib/python3.11/site-packages/pymysql/connections.py", line 548, in query
    self._affected_rows = self._read_query_result(unbuffered=unbuffered)
                          ^^^^^^^^^^^^^^^^^^^^^^^^^^^^^^^^^^^^^^^^^^^^^^
  File "/opt/homebrew/lib/python3.11/site-packages/pymysql/connections.py", line 775, in _read_query_result
    result.read()
  File "/opt/homebrew/lib/python3.11/site-packages/pymysql/connections.py", line 1156, in read
    first_packet = self.connection._read_packet()
                   ^^^^^^^^^^^^^^^^^^^^^^^^^^^^^^
  File "/opt/homebrew/lib/python3.11/site-packages/pymysql/connections.py", line 725, in _read_packet
    packet.raise_for_error()
  File "/opt/homebrew/lib/python3.11/site-packages/pymysql/protocol.py", line 221, in raise_for_error
    err.raise_mysql_exception(self._data)
  File "/opt/homebrew/lib/python3.11/site-packages/pymysql/err.py", line 143, in raise_mysql_exception
    raise errorclass(errno, errval)
pymysql.err.ProgrammingError: (1064, "You have an error in your SQL syntax; check the manual that corresponds to your MySQL server version for the right syntax to use near 'where name like '%1%'' at line 1")
 
[2023-03-23 00:53:02] [ERROR] failed to get task, error:error! 127.0.0.1 - 3306: select select * from task where status='None' where name like '%1%' failed!! 
Traceback (most recent call last):
  File "/Users/libangguo/python/project/data_canal/mysqlConnect.py", line 80, in querydata
    cursor.execute(sql)
  File "/opt/homebrew/lib/python3.11/site-packages/pymysql/cursors.py", line 148, in execute
    result = self._query(query)
             ^^^^^^^^^^^^^^^^^^
  File "/opt/homebrew/lib/python3.11/site-packages/pymysql/cursors.py", line 310, in _query
    conn.query(q)
  File "/opt/homebrew/lib/python3.11/site-packages/pymysql/connections.py", line 548, in query
    self._affected_rows = self._read_query_result(unbuffered=unbuffered)
                          ^^^^^^^^^^^^^^^^^^^^^^^^^^^^^^^^^^^^^^^^^^^^^^
  File "/opt/homebrew/lib/python3.11/site-packages/pymysql/connections.py", line 775, in _read_query_result
    result.read()
  File "/opt/homebrew/lib/python3.11/site-packages/pymysql/connections.py", line 1156, in read
    first_packet = self.connection._read_packet()
                   ^^^^^^^^^^^^^^^^^^^^^^^^^^^^^^
  File "/opt/homebrew/lib/python3.11/site-packages/pymysql/connections.py", line 725, in _read_packet
    packet.raise_for_error()
  File "/opt/homebrew/lib/python3.11/site-packages/pymysql/protocol.py", line 221, in raise_for_error
    err.raise_mysql_exception(self._data)
  File "/opt/homebrew/lib/python3.11/site-packages/pymysql/err.py", line 143, in raise_mysql_exception
    raise errorclass(errno, errval)
pymysql.err.ProgrammingError: (1064, "You have an error in your SQL syntax; check the manual that corresponds to your MySQL server version for the right syntax to use near 'where name like '%1%'' at line 1")
 
[2023-03-23 00:53:02] [ERROR] failed to get task, error:error! 127.0.0.1 - 3306: select select * from task where status='None' where name like '%1%' failed!! 
Traceback (most recent call last):
  File "/Users/libangguo/python/project/data_canal/mysqlConnect.py", line 80, in querydata
    cursor.execute(sql)
  File "/opt/homebrew/lib/python3.11/site-packages/pymysql/cursors.py", line 148, in execute
    result = self._query(query)
             ^^^^^^^^^^^^^^^^^^
  File "/opt/homebrew/lib/python3.11/site-packages/pymysql/cursors.py", line 310, in _query
    conn.query(q)
  File "/opt/homebrew/lib/python3.11/site-packages/pymysql/connections.py", line 548, in query
    self._affected_rows = self._read_query_result(unbuffered=unbuffered)
                          ^^^^^^^^^^^^^^^^^^^^^^^^^^^^^^^^^^^^^^^^^^^^^^
  File "/opt/homebrew/lib/python3.11/site-packages/pymysql/connections.py", line 775, in _read_query_result
    result.read()
  File "/opt/homebrew/lib/python3.11/site-packages/pymysql/connections.py", line 1156, in read
    first_packet = self.connection._read_packet()
                   ^^^^^^^^^^^^^^^^^^^^^^^^^^^^^^
  File "/opt/homebrew/lib/python3.11/site-packages/pymysql/connections.py", line 725, in _read_packet
    packet.raise_for_error()
  File "/opt/homebrew/lib/python3.11/site-packages/pymysql/protocol.py", line 221, in raise_for_error
    err.raise_mysql_exception(self._data)
  File "/opt/homebrew/lib/python3.11/site-packages/pymysql/err.py", line 143, in raise_mysql_exception
    raise errorclass(errno, errval)
pymysql.err.ProgrammingError: (1064, "You have an error in your SQL syntax; check the manual that corresponds to your MySQL server version for the right syntax to use near 'where name like '%1%'' at line 1")
 
[2023-03-23 00:53:02] [ERROR] failed to get task, error:error! 127.0.0.1 - 3306: select select * from task where status='None' where name like '%1%' failed!! 
Traceback (most recent call last):
  File "/Users/libangguo/python/project/data_canal/mysqlConnect.py", line 80, in querydata
    cursor.execute(sql)
  File "/opt/homebrew/lib/python3.11/site-packages/pymysql/cursors.py", line 148, in execute
    result = self._query(query)
             ^^^^^^^^^^^^^^^^^^
  File "/opt/homebrew/lib/python3.11/site-packages/pymysql/cursors.py", line 310, in _query
    conn.query(q)
  File "/opt/homebrew/lib/python3.11/site-packages/pymysql/connections.py", line 548, in query
    self._affected_rows = self._read_query_result(unbuffered=unbuffered)
                          ^^^^^^^^^^^^^^^^^^^^^^^^^^^^^^^^^^^^^^^^^^^^^^
  File "/opt/homebrew/lib/python3.11/site-packages/pymysql/connections.py", line 775, in _read_query_result
    result.read()
  File "/opt/homebrew/lib/python3.11/site-packages/pymysql/connections.py", line 1156, in read
    first_packet = self.connection._read_packet()
                   ^^^^^^^^^^^^^^^^^^^^^^^^^^^^^^
  File "/opt/homebrew/lib/python3.11/site-packages/pymysql/connections.py", line 725, in _read_packet
    packet.raise_for_error()
  File "/opt/homebrew/lib/python3.11/site-packages/pymysql/protocol.py", line 221, in raise_for_error
    err.raise_mysql_exception(self._data)
  File "/opt/homebrew/lib/python3.11/site-packages/pymysql/err.py", line 143, in raise_mysql_exception
    raise errorclass(errno, errval)
pymysql.err.ProgrammingError: (1064, "You have an error in your SQL syntax; check the manual that corresponds to your MySQL server version for the right syntax to use near 'where name like '%1%'' at line 1")
 
[2023-03-23 00:53:02] [ERROR] failed to get task, error:error! 127.0.0.1 - 3306: select select * from task where status='None' where name like '%1%' failed!! 
Traceback (most recent call last):
  File "/Users/libangguo/python/project/data_canal/mysqlConnect.py", line 80, in querydata
    cursor.execute(sql)
  File "/opt/homebrew/lib/python3.11/site-packages/pymysql/cursors.py", line 148, in execute
    result = self._query(query)
             ^^^^^^^^^^^^^^^^^^
  File "/opt/homebrew/lib/python3.11/site-packages/pymysql/cursors.py", line 310, in _query
    conn.query(q)
  File "/opt/homebrew/lib/python3.11/site-packages/pymysql/connections.py", line 548, in query
    self._affected_rows = self._read_query_result(unbuffered=unbuffered)
                          ^^^^^^^^^^^^^^^^^^^^^^^^^^^^^^^^^^^^^^^^^^^^^^
  File "/opt/homebrew/lib/python3.11/site-packages/pymysql/connections.py", line 775, in _read_query_result
    result.read()
  File "/opt/homebrew/lib/python3.11/site-packages/pymysql/connections.py", line 1156, in read
    first_packet = self.connection._read_packet()
                   ^^^^^^^^^^^^^^^^^^^^^^^^^^^^^^
  File "/opt/homebrew/lib/python3.11/site-packages/pymysql/connections.py", line 725, in _read_packet
    packet.raise_for_error()
  File "/opt/homebrew/lib/python3.11/site-packages/pymysql/protocol.py", line 221, in raise_for_error
    err.raise_mysql_exception(self._data)
  File "/opt/homebrew/lib/python3.11/site-packages/pymysql/err.py", line 143, in raise_mysql_exception
    raise errorclass(errno, errval)
pymysql.err.ProgrammingError: (1064, "You have an error in your SQL syntax; check the manual that corresponds to your MySQL server version for the right syntax to use near 'where name like '%1%'' at line 1")
 
[2023-03-23 00:53:02] [ERROR] failed to get task, error:error! 127.0.0.1 - 3306: select select * from task where status='None' where name like '%1%' failed!! 
Traceback (most recent call last):
  File "/Users/libangguo/python/project/data_canal/mysqlConnect.py", line 80, in querydata
    cursor.execute(sql)
  File "/opt/homebrew/lib/python3.11/site-packages/pymysql/cursors.py", line 148, in execute
    result = self._query(query)
             ^^^^^^^^^^^^^^^^^^
  File "/opt/homebrew/lib/python3.11/site-packages/pymysql/cursors.py", line 310, in _query
    conn.query(q)
  File "/opt/homebrew/lib/python3.11/site-packages/pymysql/connections.py", line 548, in query
    self._affected_rows = self._read_query_result(unbuffered=unbuffered)
                          ^^^^^^^^^^^^^^^^^^^^^^^^^^^^^^^^^^^^^^^^^^^^^^
  File "/opt/homebrew/lib/python3.11/site-packages/pymysql/connections.py", line 775, in _read_query_result
    result.read()
  File "/opt/homebrew/lib/python3.11/site-packages/pymysql/connections.py", line 1156, in read
    first_packet = self.connection._read_packet()
                   ^^^^^^^^^^^^^^^^^^^^^^^^^^^^^^
  File "/opt/homebrew/lib/python3.11/site-packages/pymysql/connections.py", line 725, in _read_packet
    packet.raise_for_error()
  File "/opt/homebrew/lib/python3.11/site-packages/pymysql/protocol.py", line 221, in raise_for_error
    err.raise_mysql_exception(self._data)
  File "/opt/homebrew/lib/python3.11/site-packages/pymysql/err.py", line 143, in raise_mysql_exception
    raise errorclass(errno, errval)
pymysql.err.ProgrammingError: (1064, "You have an error in your SQL syntax; check the manual that corresponds to your MySQL server version for the right syntax to use near 'where name like '%1%'' at line 1")
 
[2023-03-23 00:53:02] [ERROR] failed to get task, error:error! 127.0.0.1 - 3306: select select * from task where status='None' where name like '%1%' failed!! 
Traceback (most recent call last):
  File "/Users/libangguo/python/project/data_canal/mysqlConnect.py", line 80, in querydata
    cursor.execute(sql)
  File "/opt/homebrew/lib/python3.11/site-packages/pymysql/cursors.py", line 148, in execute
    result = self._query(query)
             ^^^^^^^^^^^^^^^^^^
  File "/opt/homebrew/lib/python3.11/site-packages/pymysql/cursors.py", line 310, in _query
    conn.query(q)
  File "/opt/homebrew/lib/python3.11/site-packages/pymysql/connections.py", line 548, in query
    self._affected_rows = self._read_query_result(unbuffered=unbuffered)
                          ^^^^^^^^^^^^^^^^^^^^^^^^^^^^^^^^^^^^^^^^^^^^^^
  File "/opt/homebrew/lib/python3.11/site-packages/pymysql/connections.py", line 775, in _read_query_result
    result.read()
  File "/opt/homebrew/lib/python3.11/site-packages/pymysql/connections.py", line 1156, in read
    first_packet = self.connection._read_packet()
                   ^^^^^^^^^^^^^^^^^^^^^^^^^^^^^^
  File "/opt/homebrew/lib/python3.11/site-packages/pymysql/connections.py", line 725, in _read_packet
    packet.raise_for_error()
  File "/opt/homebrew/lib/python3.11/site-packages/pymysql/protocol.py", line 221, in raise_for_error
    err.raise_mysql_exception(self._data)
  File "/opt/homebrew/lib/python3.11/site-packages/pymysql/err.py", line 143, in raise_mysql_exception
    raise errorclass(errno, errval)
pymysql.err.ProgrammingError: (1064, "You have an error in your SQL syntax; check the manual that corresponds to your MySQL server version for the right syntax to use near 'where name like '%1%'' at line 1")
 
[2023-03-23 00:53:02] [ERROR] failed to get task, error:error! 127.0.0.1 - 3306: select select * from task where status='None' where name like '%1%' failed!! 
Traceback (most recent call last):
  File "/Users/libangguo/python/project/data_canal/mysqlConnect.py", line 80, in querydata
    cursor.execute(sql)
  File "/opt/homebrew/lib/python3.11/site-packages/pymysql/cursors.py", line 148, in execute
    result = self._query(query)
             ^^^^^^^^^^^^^^^^^^
  File "/opt/homebrew/lib/python3.11/site-packages/pymysql/cursors.py", line 310, in _query
    conn.query(q)
  File "/opt/homebrew/lib/python3.11/site-packages/pymysql/connections.py", line 548, in query
    self._affected_rows = self._read_query_result(unbuffered=unbuffered)
                          ^^^^^^^^^^^^^^^^^^^^^^^^^^^^^^^^^^^^^^^^^^^^^^
  File "/opt/homebrew/lib/python3.11/site-packages/pymysql/connections.py", line 775, in _read_query_result
    result.read()
  File "/opt/homebrew/lib/python3.11/site-packages/pymysql/connections.py", line 1156, in read
    first_packet = self.connection._read_packet()
                   ^^^^^^^^^^^^^^^^^^^^^^^^^^^^^^
  File "/opt/homebrew/lib/python3.11/site-packages/pymysql/connections.py", line 725, in _read_packet
    packet.raise_for_error()
  File "/opt/homebrew/lib/python3.11/site-packages/pymysql/protocol.py", line 221, in raise_for_error
    err.raise_mysql_exception(self._data)
  File "/opt/homebrew/lib/python3.11/site-packages/pymysql/err.py", line 143, in raise_mysql_exception
    raise errorclass(errno, errval)
pymysql.err.ProgrammingError: (1064, "You have an error in your SQL syntax; check the manual that corresponds to your MySQL server version for the right syntax to use near 'where name like '%1%'' at line 1")
 
[2023-04-02 23:33:47] [INFO] task 55 upload success
[2023-04-02 23:35:26] [INFO] task 56 upload success
[2023-04-02 23:43:57] [ERROR] taskID: 25, failed to get pdf list, error:Traceback (most recent call last):
  File "/Users/libangguo/python/project/data_canal/download.py", line 34, in getPdfList
    pathDir = os.listdir(pdfPath)
              ^^^^^^^^^^^^^^^^^^^
FileNotFoundError: [Errno 2] No such file or directory: '/xxx'

[2023-04-02 23:43:57] [ERROR] taskID: 25, failed to get pdf list, error:Traceback (most recent call last):
  File "/Users/libangguo/python/project/data_canal/download.py", line 34, in getPdfList
    pathDir = os.listdir(pdfPath)
              ^^^^^^^^^^^^^^^^^^^
FileNotFoundError: [Errno 2] No such file or directory: '/xxx'

[2023-04-02 23:43:57] [ERROR] taskID: 25, failed to get pdf list, error:Traceback (most recent call last):
  File "/Users/libangguo/python/project/data_canal/download.py", line 34, in getPdfList
    pathDir = os.listdir(pdfPath)
              ^^^^^^^^^^^^^^^^^^^
FileNotFoundError: [Errno 2] No such file or directory: '/xxx'

[2023-04-02 23:43:57] [ERROR] taskID: 25, failed to get pdf list, error:Traceback (most recent call last):
  File "/Users/libangguo/python/project/data_canal/download.py", line 34, in getPdfList
    pathDir = os.listdir(pdfPath)
              ^^^^^^^^^^^^^^^^^^^
FileNotFoundError: [Errno 2] No such file or directory: '/xxx'

[2023-04-02 23:43:57] [ERROR] taskID: 25, failed to get pdf list, error:Traceback (most recent call last):
  File "/Users/libangguo/python/project/data_canal/download.py", line 34, in getPdfList
    pathDir = os.listdir(pdfPath)
              ^^^^^^^^^^^^^^^^^^^
FileNotFoundError: [Errno 2] No such file or directory: '/xxx'

[2023-04-02 23:43:57] [ERROR] taskID: 25, failed to get pdf list, error:Traceback (most recent call last):
  File "/Users/libangguo/python/project/data_canal/download.py", line 34, in getPdfList
    pathDir = os.listdir(pdfPath)
              ^^^^^^^^^^^^^^^^^^^
FileNotFoundError: [Errno 2] No such file or directory: '/xxx'

[2023-04-02 23:43:57] [ERROR] taskID: 25, failed to get pdf list, error:Traceback (most recent call last):
  File "/Users/libangguo/python/project/data_canal/download.py", line 34, in getPdfList
    pathDir = os.listdir(pdfPath)
              ^^^^^^^^^^^^^^^^^^^
FileNotFoundError: [Errno 2] No such file or directory: '/xxx'

[2023-04-02 23:43:57] [ERROR] taskID: 25, failed to get pdf list, error:Traceback (most recent call last):
  File "/Users/libangguo/python/project/data_canal/download.py", line 34, in getPdfList
    pathDir = os.listdir(pdfPath)
              ^^^^^^^^^^^^^^^^^^^
FileNotFoundError: [Errno 2] No such file or directory: '/xxx'

[2023-04-02 23:43:57] [ERROR] taskID: 25, failed to get pdf list, error:Traceback (most recent call last):
  File "/Users/libangguo/python/project/data_canal/download.py", line 34, in getPdfList
    pathDir = os.listdir(pdfPath)
              ^^^^^^^^^^^^^^^^^^^
FileNotFoundError: [Errno 2] No such file or directory: '/xxx'

[2023-04-02 23:43:57] [ERROR] taskID: 25, failed to get pdf list, error:Traceback (most recent call last):
  File "/Users/libangguo/python/project/data_canal/download.py", line 34, in getPdfList
    pathDir = os.listdir(pdfPath)
              ^^^^^^^^^^^^^^^^^^^
FileNotFoundError: [Errno 2] No such file or directory: '/xxx'

[2023-04-02 23:43:57] [ERROR] taskID: 25, failed to get pdf list, error:Traceback (most recent call last):
  File "/Users/libangguo/python/project/data_canal/download.py", line 34, in getPdfList
    pathDir = os.listdir(pdfPath)
              ^^^^^^^^^^^^^^^^^^^
FileNotFoundError: [Errno 2] No such file or directory: '/xxx'

[2023-04-02 23:43:57] [ERROR] taskID: 25, failed to get pdf list, error:Traceback (most recent call last):
  File "/Users/libangguo/python/project/data_canal/download.py", line 34, in getPdfList
    pathDir = os.listdir(pdfPath)
              ^^^^^^^^^^^^^^^^^^^
FileNotFoundError: [Errno 2] No such file or directory: '/xxx'

[2023-04-02 23:43:57] [ERROR] taskID: 25, failed to get pdf list, error:Traceback (most recent call last):
  File "/Users/libangguo/python/project/data_canal/download.py", line 34, in getPdfList
    pathDir = os.listdir(pdfPath)
              ^^^^^^^^^^^^^^^^^^^
FileNotFoundError: [Errno 2] No such file or directory: '/xxx'

[2023-04-02 23:44:09] [ERROR] taskID: 25, failed to get pdf list, error:Traceback (most recent call last):
  File "/Users/libangguo/python/project/data_canal/download.py", line 34, in getPdfList
    pathDir = os.listdir(pdfPath)
              ^^^^^^^^^^^^^^^^^^^
FileNotFoundError: [Errno 2] No such file or directory: '/xxx'

[2023-04-02 23:44:09] [ERROR] taskID: 25, failed to get pdf list, error:Traceback (most recent call last):
  File "/Users/libangguo/python/project/data_canal/download.py", line 34, in getPdfList
    pathDir = os.listdir(pdfPath)
              ^^^^^^^^^^^^^^^^^^^
FileNotFoundError: [Errno 2] No such file or directory: '/xxx'

[2023-04-02 23:44:09] [ERROR] taskID: 25, failed to get pdf list, error:Traceback (most recent call last):
  File "/Users/libangguo/python/project/data_canal/download.py", line 34, in getPdfList
    pathDir = os.listdir(pdfPath)
              ^^^^^^^^^^^^^^^^^^^
FileNotFoundError: [Errno 2] No such file or directory: '/xxx'

[2023-04-02 23:44:09] [ERROR] taskID: 25, failed to get pdf list, error:Traceback (most recent call last):
  File "/Users/libangguo/python/project/data_canal/download.py", line 34, in getPdfList
    pathDir = os.listdir(pdfPath)
              ^^^^^^^^^^^^^^^^^^^
FileNotFoundError: [Errno 2] No such file or directory: '/xxx'

[2023-04-02 23:44:09] [ERROR] taskID: 25, failed to get pdf list, error:Traceback (most recent call last):
  File "/Users/libangguo/python/project/data_canal/download.py", line 34, in getPdfList
    pathDir = os.listdir(pdfPath)
              ^^^^^^^^^^^^^^^^^^^
FileNotFoundError: [Errno 2] No such file or directory: '/xxx'

[2023-04-02 23:44:09] [ERROR] taskID: 25, failed to get pdf list, error:Traceback (most recent call last):
  File "/Users/libangguo/python/project/data_canal/download.py", line 34, in getPdfList
    pathDir = os.listdir(pdfPath)
              ^^^^^^^^^^^^^^^^^^^
FileNotFoundError: [Errno 2] No such file or directory: '/xxx'

[2023-04-02 23:44:09] [ERROR] taskID: 25, failed to get pdf list, error:Traceback (most recent call last):
  File "/Users/libangguo/python/project/data_canal/download.py", line 34, in getPdfList
    pathDir = os.listdir(pdfPath)
              ^^^^^^^^^^^^^^^^^^^
FileNotFoundError: [Errno 2] No such file or directory: '/xxx'

[2023-04-02 23:44:09] [ERROR] taskID: 25, failed to get pdf list, error:Traceback (most recent call last):
  File "/Users/libangguo/python/project/data_canal/download.py", line 34, in getPdfList
    pathDir = os.listdir(pdfPath)
              ^^^^^^^^^^^^^^^^^^^
FileNotFoundError: [Errno 2] No such file or directory: '/xxx'

[2023-04-02 23:44:09] [ERROR] taskID: 25, failed to get pdf list, error:Traceback (most recent call last):
  File "/Users/libangguo/python/project/data_canal/download.py", line 34, in getPdfList
    pathDir = os.listdir(pdfPath)
              ^^^^^^^^^^^^^^^^^^^
FileNotFoundError: [Errno 2] No such file or directory: '/xxx'

[2023-04-02 23:44:09] [ERROR] taskID: 25, failed to get pdf list, error:Traceback (most recent call last):
  File "/Users/libangguo/python/project/data_canal/download.py", line 34, in getPdfList
    pathDir = os.listdir(pdfPath)
              ^^^^^^^^^^^^^^^^^^^
FileNotFoundError: [Errno 2] No such file or directory: '/xxx'

[2023-04-02 23:44:09] [ERROR] taskID: 25, failed to get pdf list, error:Traceback (most recent call last):
  File "/Users/libangguo/python/project/data_canal/download.py", line 34, in getPdfList
    pathDir = os.listdir(pdfPath)
              ^^^^^^^^^^^^^^^^^^^
FileNotFoundError: [Errno 2] No such file or directory: '/xxx'

[2023-04-02 23:44:09] [ERROR] taskID: 25, failed to get pdf list, error:Traceback (most recent call last):
  File "/Users/libangguo/python/project/data_canal/download.py", line 34, in getPdfList
    pathDir = os.listdir(pdfPath)
              ^^^^^^^^^^^^^^^^^^^
FileNotFoundError: [Errno 2] No such file or directory: '/xxx'

[2023-04-02 23:44:09] [ERROR] taskID: 25, failed to get pdf list, error:Traceback (most recent call last):
  File "/Users/libangguo/python/project/data_canal/download.py", line 34, in getPdfList
    pathDir = os.listdir(pdfPath)
              ^^^^^^^^^^^^^^^^^^^
FileNotFoundError: [Errno 2] No such file or directory: '/xxx'

[2023-04-02 23:44:09] [ERROR] taskID: 25, failed to get pdf list, error:Traceback (most recent call last):
  File "/Users/libangguo/python/project/data_canal/download.py", line 34, in getPdfList
    pathDir = os.listdir(pdfPath)
              ^^^^^^^^^^^^^^^^^^^
FileNotFoundError: [Errno 2] No such file or directory: '/xxx'

[2023-04-02 23:45:28] [ERROR] taskID: 25, failed to get pdf list, error:Traceback (most recent call last):
  File "/Users/libangguo/python/project/data_canal/download.py", line 34, in getPdfList
    pathDir = os.listdir(pdfPath)
              ^^^^^^^^^^^^^^^^^^^
FileNotFoundError: [Errno 2] No such file or directory: '/xxx'

[2023-04-02 23:45:28] [ERROR] taskID: 25, failed to get pdf list, error:Traceback (most recent call last):
  File "/Users/libangguo/python/project/data_canal/download.py", line 34, in getPdfList
    pathDir = os.listdir(pdfPath)
              ^^^^^^^^^^^^^^^^^^^
FileNotFoundError: [Errno 2] No such file or directory: '/xxx'

[2023-04-02 23:45:28] [ERROR] taskID: 25, failed to get pdf list, error:Traceback (most recent call last):
  File "/Users/libangguo/python/project/data_canal/download.py", line 34, in getPdfList
    pathDir = os.listdir(pdfPath)
              ^^^^^^^^^^^^^^^^^^^
FileNotFoundError: [Errno 2] No such file or directory: '/xxx'

[2023-04-02 23:45:28] [ERROR] taskID: 25, failed to get pdf list, error:Traceback (most recent call last):
  File "/Users/libangguo/python/project/data_canal/download.py", line 34, in getPdfList
    pathDir = os.listdir(pdfPath)
              ^^^^^^^^^^^^^^^^^^^
FileNotFoundError: [Errno 2] No such file or directory: '/xxx'

[2023-04-02 23:45:28] [ERROR] taskID: 25, failed to get pdf list, error:Traceback (most recent call last):
  File "/Users/libangguo/python/project/data_canal/download.py", line 34, in getPdfList
    pathDir = os.listdir(pdfPath)
              ^^^^^^^^^^^^^^^^^^^
FileNotFoundError: [Errno 2] No such file or directory: '/xxx'

[2023-04-02 23:45:28] [ERROR] taskID: 25, failed to get pdf list, error:Traceback (most recent call last):
  File "/Users/libangguo/python/project/data_canal/download.py", line 34, in getPdfList
    pathDir = os.listdir(pdfPath)
              ^^^^^^^^^^^^^^^^^^^
FileNotFoundError: [Errno 2] No such file or directory: '/xxx'

[2023-04-02 23:45:28] [ERROR] taskID: 25, failed to get pdf list, error:Traceback (most recent call last):
  File "/Users/libangguo/python/project/data_canal/download.py", line 34, in getPdfList
    pathDir = os.listdir(pdfPath)
              ^^^^^^^^^^^^^^^^^^^
FileNotFoundError: [Errno 2] No such file or directory: '/xxx'

[2023-04-02 23:45:28] [ERROR] taskID: 25, failed to get pdf list, error:Traceback (most recent call last):
  File "/Users/libangguo/python/project/data_canal/download.py", line 34, in getPdfList
    pathDir = os.listdir(pdfPath)
              ^^^^^^^^^^^^^^^^^^^
FileNotFoundError: [Errno 2] No such file or directory: '/xxx'

[2023-04-02 23:45:28] [ERROR] taskID: 25, failed to get pdf list, error:Traceback (most recent call last):
  File "/Users/libangguo/python/project/data_canal/download.py", line 34, in getPdfList
    pathDir = os.listdir(pdfPath)
              ^^^^^^^^^^^^^^^^^^^
FileNotFoundError: [Errno 2] No such file or directory: '/xxx'

[2023-04-02 23:45:28] [ERROR] taskID: 25, failed to get pdf list, error:Traceback (most recent call last):
  File "/Users/libangguo/python/project/data_canal/download.py", line 34, in getPdfList
    pathDir = os.listdir(pdfPath)
              ^^^^^^^^^^^^^^^^^^^
FileNotFoundError: [Errno 2] No such file or directory: '/xxx'

[2023-04-02 23:45:28] [ERROR] taskID: 25, failed to get pdf list, error:Traceback (most recent call last):
  File "/Users/libangguo/python/project/data_canal/download.py", line 34, in getPdfList
    pathDir = os.listdir(pdfPath)
              ^^^^^^^^^^^^^^^^^^^
FileNotFoundError: [Errno 2] No such file or directory: '/xxx'

[2023-04-02 23:45:28] [ERROR] taskID: 25, failed to get pdf list, error:Traceback (most recent call last):
  File "/Users/libangguo/python/project/data_canal/download.py", line 34, in getPdfList
    pathDir = os.listdir(pdfPath)
              ^^^^^^^^^^^^^^^^^^^
FileNotFoundError: [Errno 2] No such file or directory: '/xxx'

[2023-04-02 23:45:28] [ERROR] taskID: 25, failed to get pdf list, error:Traceback (most recent call last):
  File "/Users/libangguo/python/project/data_canal/download.py", line 34, in getPdfList
    pathDir = os.listdir(pdfPath)
              ^^^^^^^^^^^^^^^^^^^
FileNotFoundError: [Errno 2] No such file or directory: '/xxx'

[2023-04-02 23:45:28] [ERROR] taskID: 25, failed to get pdf list, error:Traceback (most recent call last):
  File "/Users/libangguo/python/project/data_canal/download.py", line 34, in getPdfList
    pathDir = os.listdir(pdfPath)
              ^^^^^^^^^^^^^^^^^^^
FileNotFoundError: [Errno 2] No such file or directory: '/xxx'

[2023-04-02 23:45:28] [ERROR] taskID: 25, failed to get pdf list, error:Traceback (most recent call last):
  File "/Users/libangguo/python/project/data_canal/download.py", line 34, in getPdfList
    pathDir = os.listdir(pdfPath)
              ^^^^^^^^^^^^^^^^^^^
FileNotFoundError: [Errno 2] No such file or directory: '/xxx'

[2023-04-02 23:45:28] [ERROR] taskID: 25, failed to get pdf list, error:Traceback (most recent call last):
  File "/Users/libangguo/python/project/data_canal/download.py", line 34, in getPdfList
    pathDir = os.listdir(pdfPath)
              ^^^^^^^^^^^^^^^^^^^
FileNotFoundError: [Errno 2] No such file or directory: '/xxx'

[2023-04-02 23:45:28] [ERROR] taskID: 25, failed to get pdf list, error:Traceback (most recent call last):
  File "/Users/libangguo/python/project/data_canal/download.py", line 34, in getPdfList
    pathDir = os.listdir(pdfPath)
              ^^^^^^^^^^^^^^^^^^^
FileNotFoundError: [Errno 2] No such file or directory: '/xxx'

[2023-04-02 23:45:28] [ERROR] taskID: 25, failed to get pdf list, error:Traceback (most recent call last):
  File "/Users/libangguo/python/project/data_canal/download.py", line 34, in getPdfList
    pathDir = os.listdir(pdfPath)
              ^^^^^^^^^^^^^^^^^^^
FileNotFoundError: [Errno 2] No such file or directory: '/xxx'

[2023-04-02 23:45:28] [ERROR] taskID: 25, failed to get pdf list, error:Traceback (most recent call last):
  File "/Users/libangguo/python/project/data_canal/download.py", line 34, in getPdfList
    pathDir = os.listdir(pdfPath)
              ^^^^^^^^^^^^^^^^^^^
FileNotFoundError: [Errno 2] No such file or directory: '/xxx'

[2023-04-02 23:45:28] [ERROR] taskID: 25, failed to get pdf list, error:Traceback (most recent call last):
  File "/Users/libangguo/python/project/data_canal/download.py", line 34, in getPdfList
    pathDir = os.listdir(pdfPath)
              ^^^^^^^^^^^^^^^^^^^
FileNotFoundError: [Errno 2] No such file or directory: '/xxx'

[2023-04-02 23:45:28] [ERROR] taskID: 25, failed to get pdf list, error:Traceback (most recent call last):
  File "/Users/libangguo/python/project/data_canal/download.py", line 34, in getPdfList
    pathDir = os.listdir(pdfPath)
              ^^^^^^^^^^^^^^^^^^^
FileNotFoundError: [Errno 2] No such file or directory: '/xxx'

[2023-04-02 23:45:28] [ERROR] taskID: 25, failed to get pdf list, error:Traceback (most recent call last):
  File "/Users/libangguo/python/project/data_canal/download.py", line 34, in getPdfList
    pathDir = os.listdir(pdfPath)
              ^^^^^^^^^^^^^^^^^^^
FileNotFoundError: [Errno 2] No such file or directory: '/xxx'

[2023-04-02 23:46:47] [ERROR] taskID: 25, failed to get pdf list, error:Traceback (most recent call last):
  File "/Users/libangguo/python/project/data_canal/download.py", line 34, in getPdfList
    pathDir = os.listdir(pdfPath)
              ^^^^^^^^^^^^^^^^^^^
FileNotFoundError: [Errno 2] No such file or directory: '/xxx'

[2023-04-02 23:46:47] [ERROR] taskID: 25, failed to get pdf list, error:Traceback (most recent call last):
  File "/Users/libangguo/python/project/data_canal/download.py", line 34, in getPdfList
    pathDir = os.listdir(pdfPath)
              ^^^^^^^^^^^^^^^^^^^
FileNotFoundError: [Errno 2] No such file or directory: '/xxx'

[2023-04-02 23:46:47] [ERROR] taskID: 25, failed to get pdf list, error:Traceback (most recent call last):
  File "/Users/libangguo/python/project/data_canal/download.py", line 34, in getPdfList
    pathDir = os.listdir(pdfPath)
              ^^^^^^^^^^^^^^^^^^^
FileNotFoundError: [Errno 2] No such file or directory: '/xxx'

[2023-04-02 23:46:47] [ERROR] taskID: 25, failed to get pdf list, error:Traceback (most recent call last):
  File "/Users/libangguo/python/project/data_canal/download.py", line 34, in getPdfList
    pathDir = os.listdir(pdfPath)
              ^^^^^^^^^^^^^^^^^^^
FileNotFoundError: [Errno 2] No such file or directory: '/xxx'

[2023-04-02 23:46:47] [ERROR] taskID: 25, failed to get pdf list, error:Traceback (most recent call last):
  File "/Users/libangguo/python/project/data_canal/download.py", line 34, in getPdfList
    pathDir = os.listdir(pdfPath)
              ^^^^^^^^^^^^^^^^^^^
FileNotFoundError: [Errno 2] No such file or directory: '/xxx'

[2023-04-02 23:46:47] [ERROR] taskID: 25, failed to get pdf list, error:Traceback (most recent call last):
  File "/Users/libangguo/python/project/data_canal/download.py", line 34, in getPdfList
    pathDir = os.listdir(pdfPath)
              ^^^^^^^^^^^^^^^^^^^
FileNotFoundError: [Errno 2] No such file or directory: '/xxx'

[2023-04-02 23:46:47] [ERROR] taskID: 25, failed to get pdf list, error:Traceback (most recent call last):
  File "/Users/libangguo/python/project/data_canal/download.py", line 34, in getPdfList
    pathDir = os.listdir(pdfPath)
              ^^^^^^^^^^^^^^^^^^^
FileNotFoundError: [Errno 2] No such file or directory: '/xxx'

[2023-04-02 23:46:47] [ERROR] taskID: 25, failed to get pdf list, error:Traceback (most recent call last):
  File "/Users/libangguo/python/project/data_canal/download.py", line 34, in getPdfList
    pathDir = os.listdir(pdfPath)
              ^^^^^^^^^^^^^^^^^^^
FileNotFoundError: [Errno 2] No such file or directory: '/xxx'

[2023-04-02 23:46:47] [ERROR] taskID: 25, failed to get pdf list, error:Traceback (most recent call last):
  File "/Users/libangguo/python/project/data_canal/download.py", line 34, in getPdfList
    pathDir = os.listdir(pdfPath)
              ^^^^^^^^^^^^^^^^^^^
FileNotFoundError: [Errno 2] No such file or directory: '/xxx'

[2023-04-02 23:46:47] [ERROR] taskID: 25, failed to get pdf list, error:Traceback (most recent call last):
  File "/Users/libangguo/python/project/data_canal/download.py", line 34, in getPdfList
    pathDir = os.listdir(pdfPath)
              ^^^^^^^^^^^^^^^^^^^
FileNotFoundError: [Errno 2] No such file or directory: '/xxx'

[2023-04-02 23:46:47] [ERROR] taskID: 25, failed to get pdf list, error:Traceback (most recent call last):
  File "/Users/libangguo/python/project/data_canal/download.py", line 34, in getPdfList
    pathDir = os.listdir(pdfPath)
              ^^^^^^^^^^^^^^^^^^^
FileNotFoundError: [Errno 2] No such file or directory: '/xxx'

[2023-04-02 23:46:47] [ERROR] taskID: 25, failed to get pdf list, error:Traceback (most recent call last):
  File "/Users/libangguo/python/project/data_canal/download.py", line 34, in getPdfList
    pathDir = os.listdir(pdfPath)
              ^^^^^^^^^^^^^^^^^^^
FileNotFoundError: [Errno 2] No such file or directory: '/xxx'

[2023-04-02 23:46:47] [ERROR] taskID: 25, failed to get pdf list, error:Traceback (most recent call last):
  File "/Users/libangguo/python/project/data_canal/download.py", line 34, in getPdfList
    pathDir = os.listdir(pdfPath)
              ^^^^^^^^^^^^^^^^^^^
FileNotFoundError: [Errno 2] No such file or directory: '/xxx'

[2023-04-02 23:46:47] [ERROR] taskID: 25, failed to get pdf list, error:Traceback (most recent call last):
  File "/Users/libangguo/python/project/data_canal/download.py", line 34, in getPdfList
    pathDir = os.listdir(pdfPath)
              ^^^^^^^^^^^^^^^^^^^
FileNotFoundError: [Errno 2] No such file or directory: '/xxx'

[2023-04-02 23:46:47] [ERROR] taskID: 25, failed to get pdf list, error:Traceback (most recent call last):
  File "/Users/libangguo/python/project/data_canal/download.py", line 34, in getPdfList
    pathDir = os.listdir(pdfPath)
              ^^^^^^^^^^^^^^^^^^^
FileNotFoundError: [Errno 2] No such file or directory: '/xxx'

[2023-04-02 23:46:47] [ERROR] taskID: 25, failed to get pdf list, error:Traceback (most recent call last):
  File "/Users/libangguo/python/project/data_canal/download.py", line 34, in getPdfList
    pathDir = os.listdir(pdfPath)
              ^^^^^^^^^^^^^^^^^^^
FileNotFoundError: [Errno 2] No such file or directory: '/xxx'

[2023-04-02 23:46:47] [ERROR] taskID: 25, failed to get pdf list, error:Traceback (most recent call last):
  File "/Users/libangguo/python/project/data_canal/download.py", line 34, in getPdfList
    pathDir = os.listdir(pdfPath)
              ^^^^^^^^^^^^^^^^^^^
FileNotFoundError: [Errno 2] No such file or directory: '/xxx'

[2023-04-02 23:46:47] [ERROR] taskID: 25, failed to get pdf list, error:Traceback (most recent call last):
  File "/Users/libangguo/python/project/data_canal/download.py", line 34, in getPdfList
    pathDir = os.listdir(pdfPath)
              ^^^^^^^^^^^^^^^^^^^
FileNotFoundError: [Errno 2] No such file or directory: '/xxx'

[2023-04-02 23:46:47] [ERROR] taskID: 25, failed to get pdf list, error:Traceback (most recent call last):
  File "/Users/libangguo/python/project/data_canal/download.py", line 34, in getPdfList
    pathDir = os.listdir(pdfPath)
              ^^^^^^^^^^^^^^^^^^^
FileNotFoundError: [Errno 2] No such file or directory: '/xxx'

[2023-04-02 23:46:47] [ERROR] taskID: 25, failed to get pdf list, error:Traceback (most recent call last):
  File "/Users/libangguo/python/project/data_canal/download.py", line 34, in getPdfList
    pathDir = os.listdir(pdfPath)
              ^^^^^^^^^^^^^^^^^^^
FileNotFoundError: [Errno 2] No such file or directory: '/xxx'

[2023-04-02 23:46:47] [ERROR] taskID: 25, failed to get pdf list, error:Traceback (most recent call last):
  File "/Users/libangguo/python/project/data_canal/download.py", line 34, in getPdfList
    pathDir = os.listdir(pdfPath)
              ^^^^^^^^^^^^^^^^^^^
FileNotFoundError: [Errno 2] No such file or directory: '/xxx'

[2023-04-02 23:46:47] [ERROR] taskID: 25, failed to get pdf list, error:Traceback (most recent call last):
  File "/Users/libangguo/python/project/data_canal/download.py", line 34, in getPdfList
    pathDir = os.listdir(pdfPath)
              ^^^^^^^^^^^^^^^^^^^
FileNotFoundError: [Errno 2] No such file or directory: '/xxx'

[2023-04-02 23:46:47] [ERROR] taskID: 25, failed to get pdf list, error:Traceback (most recent call last):
  File "/Users/libangguo/python/project/data_canal/download.py", line 34, in getPdfList
    pathDir = os.listdir(pdfPath)
              ^^^^^^^^^^^^^^^^^^^
FileNotFoundError: [Errno 2] No such file or directory: '/xxx'

[2023-04-02 23:46:47] [ERROR] taskID: 25, failed to get pdf list, error:Traceback (most recent call last):
  File "/Users/libangguo/python/project/data_canal/download.py", line 34, in getPdfList
    pathDir = os.listdir(pdfPath)
              ^^^^^^^^^^^^^^^^^^^
FileNotFoundError: [Errno 2] No such file or directory: '/xxx'

[2023-04-02 23:48:36] [ERROR] taskID: 25, failed to get pdf list, error:Traceback (most recent call last):
  File "/Users/libangguo/python/project/data_canal/download.py", line 34, in getPdfList
    pathDir = os.listdir(pdfPath)
              ^^^^^^^^^^^^^^^^^^^
FileNotFoundError: [Errno 2] No such file or directory: '/xxx'

[2023-04-02 23:48:36] [ERROR] taskID: 25, failed to get pdf list, error:Traceback (most recent call last):
  File "/Users/libangguo/python/project/data_canal/download.py", line 34, in getPdfList
    pathDir = os.listdir(pdfPath)
              ^^^^^^^^^^^^^^^^^^^
FileNotFoundError: [Errno 2] No such file or directory: '/xxx'

[2023-04-02 23:48:36] [ERROR] taskID: 25, failed to get pdf list, error:Traceback (most recent call last):
  File "/Users/libangguo/python/project/data_canal/download.py", line 34, in getPdfList
    pathDir = os.listdir(pdfPath)
              ^^^^^^^^^^^^^^^^^^^
FileNotFoundError: [Errno 2] No such file or directory: '/xxx'

[2023-04-02 23:48:36] [ERROR] taskID: 25, failed to get pdf list, error:Traceback (most recent call last):
  File "/Users/libangguo/python/project/data_canal/download.py", line 34, in getPdfList
    pathDir = os.listdir(pdfPath)
              ^^^^^^^^^^^^^^^^^^^
FileNotFoundError: [Errno 2] No such file or directory: '/xxx'

[2023-04-02 23:48:36] [ERROR] taskID: 25, failed to get pdf list, error:Traceback (most recent call last):
  File "/Users/libangguo/python/project/data_canal/download.py", line 34, in getPdfList
    pathDir = os.listdir(pdfPath)
              ^^^^^^^^^^^^^^^^^^^
FileNotFoundError: [Errno 2] No such file or directory: '/xxx'

[2023-04-02 23:48:36] [ERROR] taskID: 25, failed to get pdf list, error:Traceback (most recent call last):
  File "/Users/libangguo/python/project/data_canal/download.py", line 34, in getPdfList
    pathDir = os.listdir(pdfPath)
              ^^^^^^^^^^^^^^^^^^^
FileNotFoundError: [Errno 2] No such file or directory: '/xxx'

[2023-04-02 23:48:36] [ERROR] taskID: 25, failed to get pdf list, error:Traceback (most recent call last):
  File "/Users/libangguo/python/project/data_canal/download.py", line 34, in getPdfList
    pathDir = os.listdir(pdfPath)
              ^^^^^^^^^^^^^^^^^^^
FileNotFoundError: [Errno 2] No such file or directory: '/xxx'

[2023-04-02 23:48:36] [ERROR] taskID: 25, failed to get pdf list, error:Traceback (most recent call last):
  File "/Users/libangguo/python/project/data_canal/download.py", line 34, in getPdfList
    pathDir = os.listdir(pdfPath)
              ^^^^^^^^^^^^^^^^^^^
FileNotFoundError: [Errno 2] No such file or directory: '/xxx'

[2023-04-02 23:48:36] [ERROR] taskID: 25, failed to get pdf list, error:Traceback (most recent call last):
  File "/Users/libangguo/python/project/data_canal/download.py", line 34, in getPdfList
    pathDir = os.listdir(pdfPath)
              ^^^^^^^^^^^^^^^^^^^
FileNotFoundError: [Errno 2] No such file or directory: '/xxx'

[2023-04-02 23:48:36] [ERROR] taskID: 25, failed to get pdf list, error:Traceback (most recent call last):
  File "/Users/libangguo/python/project/data_canal/download.py", line 34, in getPdfList
    pathDir = os.listdir(pdfPath)
              ^^^^^^^^^^^^^^^^^^^
FileNotFoundError: [Errno 2] No such file or directory: '/xxx'

[2023-04-02 23:48:36] [ERROR] taskID: 25, failed to get pdf list, error:Traceback (most recent call last):
  File "/Users/libangguo/python/project/data_canal/download.py", line 34, in getPdfList
    pathDir = os.listdir(pdfPath)
              ^^^^^^^^^^^^^^^^^^^
FileNotFoundError: [Errno 2] No such file or directory: '/xxx'

[2023-04-02 23:48:36] [ERROR] taskID: 25, failed to get pdf list, error:Traceback (most recent call last):
  File "/Users/libangguo/python/project/data_canal/download.py", line 34, in getPdfList
    pathDir = os.listdir(pdfPath)
              ^^^^^^^^^^^^^^^^^^^
FileNotFoundError: [Errno 2] No such file or directory: '/xxx'

[2023-04-02 23:48:36] [ERROR] taskID: 25, failed to get pdf list, error:Traceback (most recent call last):
  File "/Users/libangguo/python/project/data_canal/download.py", line 34, in getPdfList
    pathDir = os.listdir(pdfPath)
              ^^^^^^^^^^^^^^^^^^^
FileNotFoundError: [Errno 2] No such file or directory: '/xxx'

[2023-04-02 23:48:36] [ERROR] taskID: 25, failed to get pdf list, error:Traceback (most recent call last):
  File "/Users/libangguo/python/project/data_canal/download.py", line 34, in getPdfList
    pathDir = os.listdir(pdfPath)
              ^^^^^^^^^^^^^^^^^^^
FileNotFoundError: [Errno 2] No such file or directory: '/xxx'

[2023-04-02 23:48:36] [ERROR] taskID: 25, failed to get pdf list, error:Traceback (most recent call last):
  File "/Users/libangguo/python/project/data_canal/download.py", line 34, in getPdfList
    pathDir = os.listdir(pdfPath)
              ^^^^^^^^^^^^^^^^^^^
FileNotFoundError: [Errno 2] No such file or directory: '/xxx'

[2023-04-02 23:48:36] [ERROR] taskID: 25, failed to get pdf list, error:Traceback (most recent call last):
  File "/Users/libangguo/python/project/data_canal/download.py", line 34, in getPdfList
    pathDir = os.listdir(pdfPath)
              ^^^^^^^^^^^^^^^^^^^
FileNotFoundError: [Errno 2] No such file or directory: '/xxx'

[2023-04-02 23:48:36] [ERROR] taskID: 25, failed to get pdf list, error:Traceback (most recent call last):
  File "/Users/libangguo/python/project/data_canal/download.py", line 34, in getPdfList
    pathDir = os.listdir(pdfPath)
              ^^^^^^^^^^^^^^^^^^^
FileNotFoundError: [Errno 2] No such file or directory: '/xxx'

[2023-04-02 23:48:36] [ERROR] taskID: 25, failed to get pdf list, error:Traceback (most recent call last):
  File "/Users/libangguo/python/project/data_canal/download.py", line 34, in getPdfList
    pathDir = os.listdir(pdfPath)
              ^^^^^^^^^^^^^^^^^^^
FileNotFoundError: [Errno 2] No such file or directory: '/xxx'

[2023-04-02 23:48:36] [ERROR] taskID: 25, failed to get pdf list, error:Traceback (most recent call last):
  File "/Users/libangguo/python/project/data_canal/download.py", line 34, in getPdfList
    pathDir = os.listdir(pdfPath)
              ^^^^^^^^^^^^^^^^^^^
FileNotFoundError: [Errno 2] No such file or directory: '/xxx'

[2023-04-02 23:48:36] [ERROR] taskID: 25, failed to get pdf list, error:Traceback (most recent call last):
  File "/Users/libangguo/python/project/data_canal/download.py", line 34, in getPdfList
    pathDir = os.listdir(pdfPath)
              ^^^^^^^^^^^^^^^^^^^
FileNotFoundError: [Errno 2] No such file or directory: '/xxx'

[2023-04-02 23:48:36] [ERROR] taskID: 25, failed to get pdf list, error:Traceback (most recent call last):
  File "/Users/libangguo/python/project/data_canal/download.py", line 34, in getPdfList
    pathDir = os.listdir(pdfPath)
              ^^^^^^^^^^^^^^^^^^^
FileNotFoundError: [Errno 2] No such file or directory: '/xxx'

[2023-04-02 23:48:36] [ERROR] taskID: 25, failed to get pdf list, error:Traceback (most recent call last):
  File "/Users/libangguo/python/project/data_canal/download.py", line 34, in getPdfList
    pathDir = os.listdir(pdfPath)
              ^^^^^^^^^^^^^^^^^^^
FileNotFoundError: [Errno 2] No such file or directory: '/xxx'

[2023-04-02 23:48:36] [ERROR] taskID: 25, failed to get pdf list, error:Traceback (most recent call last):
  File "/Users/libangguo/python/project/data_canal/download.py", line 34, in getPdfList
    pathDir = os.listdir(pdfPath)
              ^^^^^^^^^^^^^^^^^^^
FileNotFoundError: [Errno 2] No such file or directory: '/xxx'

[2023-04-02 23:48:36] [ERROR] taskID: 25, failed to get pdf list, error:Traceback (most recent call last):
  File "/Users/libangguo/python/project/data_canal/download.py", line 34, in getPdfList
    pathDir = os.listdir(pdfPath)
              ^^^^^^^^^^^^^^^^^^^
FileNotFoundError: [Errno 2] No such file or directory: '/xxx'

[2023-04-02 23:48:36] [ERROR] taskID: 25, failed to get pdf list, error:Traceback (most recent call last):
  File "/Users/libangguo/python/project/data_canal/download.py", line 34, in getPdfList
    pathDir = os.listdir(pdfPath)
              ^^^^^^^^^^^^^^^^^^^
FileNotFoundError: [Errno 2] No such file or directory: '/xxx'

[2023-04-02 23:48:36] [ERROR] taskID: 25, failed to get pdf list, error:Traceback (most recent call last):
  File "/Users/libangguo/python/project/data_canal/download.py", line 34, in getPdfList
    pathDir = os.listdir(pdfPath)
              ^^^^^^^^^^^^^^^^^^^
FileNotFoundError: [Errno 2] No such file or directory: '/xxx'

